Workbook
Name Burndown: Sprint!$J$4:$CD$67
Name Burndown: Sprint!$J$4:$CD$67
Name BurndownColumns: Analysis!$E$44
Name BurndownColumns: Analysis!$E$44
Name DailyScrumDateModifier: Analysis!$E$41
Name DailyScrumDateModifier: Analysis!$E$41
Name Deliverable: 'Project Specific Reports'!$A$9:$A$24
Name HoursLeftColumn: Analysis!$E$46
Name HoursLeftColumn: Analysis!$E$46
Name HoursSpentColumn: Analysis!$E$45
Name HoursSpentColumn: Analysis!$E$45
Name LastRow: Sprint!#REF!
Name LeftColumn: Analysis!$E$46
Name LeftColumn: Analysis!$E$46
Name Members: OFFSET('Team Roster'!$D$8,0,0,COUNTA('Team Roster'!$D:$D)-1,1)
Name Members: OFFSET('Team Roster'!$D$8,0,0,COUNTA('Team Roster'!$D:$D)-1,1)
Name Members: OFFSET('Team Roster'!$D$8,0,0,COUNTA('Team Roster'!$D:$D)-1,1)
Name SkipWeekends: Analysis!$E$40
Name SkipWeekends: Analysis!$E$40
Name SpentColumn: Analysis!$E$45
Name SpentColumn: Analysis!$E$45
Name SprintDates: Sprint!$J$1:$CD$1
Name SprintDates: Sprint!$J$1:$CD$1
Name SprintStart: Capacity!$E$3
Name Start_Date: Capacity!$E$3
Name StatusColumn: Analysis!$E$47
Name StatusColumn: Analysis!$E$47
Name StatusTypes: Analysis!$A$50:$A$50
Name StatusTypes: Analysis!$A$50:$A$50
Name TotalEffort: Sprint!$CE$4:$CE$67
Name TotalEffort: Sprint!$CE$4:$CE$67
Name Worktype: 'Project Specific Reports'!$A$2:$A$5

Sheet Team Roster
B4: Sprint Vision: | C4: Actividad 12
B6: Sprint Team | C6: Name | D6: Alias | E6: Primary Phone | F6: Mobile Phone | G6: Alternate Email | H6: Instant Messaging
C7: Diego | D7: DIE | E7: - | F7: - | G7: diego@equipo.com | H7: Teams
C8: Irma | D8: IRM | E8: - | F8: - | G8: irma@equipo.com | H8: Teams
C9: Integrante 3 | D9: INT3 | E9: - | F9: - | G9: int3@equipo.com | H9: Teams
C10: Integrante 4 | D10: INT4 | E10: - | F10: - | G10: int4@equipo.com | H10: Teams
C11: Scrum Master | D11: SM | E11: - | F11: - | G11: sm@equipo.com | H11: Teams
C12: Product Owner | D12: PO | E12: - | F12: - | G12: po@equipo.com | H12: Teams
C13: Cesar | D13: Cesar | E13: Phone | F13: Mobile | G13: Alt Email | H13: IM Information
C14: Unassigned | D14: Unassigned | E14: Phone | F14: Mobile | G14: Alt Email | H14: IM Information
C15: Unassigned | D15: Unassigned | E15: Phone | F15: Mobile | G15: Alt Email | H15: IM Information

Sheet Capacity
B2: Current Date | D2: =TEXT(E2,"ddd") -> Fri | E2: =TODAY() -> 46143
B3: Sprint Start Date | D3: =TEXT(E3,"ddd") -> Fri | E3: 46143
B5: Sprint Tracking Statistics
B6: Productive Hours = | C6: 8 | E6: Sprint Days = | F6: 12 | I6: 46143 | J6: =I6+1 -> 46144 | K6: =J6+1 -> 46145 | L6: =K6+1 -> 46146 | M6: =L6+1 -> 46147 | N6: =M6+1 -> 46148 | O6: =N6+1 -> 46149 | P6: 46154 | Q6: =P6+1 -> 46155 | R6: =Q6+1 -> 46156 | S6: =R6+1 -> 46157 | T6: =S6+1 -> 46158 | U6: =T6+1 -> 46159 | V6: =U6+1 -> 46160
E7: Scrum Team | F7: %age of time on Project | G7: Assigned Hours | I7: F | J7: M | K7: T | L7: W | M7: T | N7: F | O7: M | P7: T | Q7: W | R7: T | S7: F | T7: M | W7: Available Hours
B8: Total Remaining Hours: | C8: =SUM(G8:G25) -> 340 | E8: DIE | F8: 1 | G8: 80 | I8: =IF(I$6<$E$3,0,IF(ISBLANK($E8),0,IF(I$6<$E$2,0,1))) -> 1 | J8: =IF(J$6<$E$3,0,IF(ISBLANK($E8),0,IF(J$6<$E$2,0,1))) -> 1 | K8: =IF(K$6<$E$3,0,IF(ISBLANK($E8),0,IF(K$6<$E$2,0,1))) -> 1 | L8: =IF(L$6<$E$3,0,IF(ISBLANK($E8),0,IF(L$6<$E$2,0,1))) -> 1 | M8: =IF(M$6<$E$3,0,IF(ISBLANK($E8),0,IF(M$6<$E$2,0,1))) -> 1 | N8: 8 | O8: 8 | P8: =IF(P$6<$E$3,0,IF(ISBLANK($E8),0,IF(P$6<$E$2,0,1))) -> 1 | Q8: =IF(Q$6<$E$3,0,IF(ISBLANK($E8),0,IF(Q$6<$E$2,0,1))) -> 1 | R8: =IF(R$6<$E$3,0,IF(ISBLANK($E8),0,IF(R$6<$E$2,0,1))) -> 1 | S8: =IF(S$6<$E$3,0,IF(ISBLANK($E8),0,IF(S$6<$E$2,0,1))) -> 1 | T8: =IF(T$6<$E$3,0,IF(ISBLANK($E8),0,IF(T$6<$E$2,0,1))) -> 1 | W8: =IF(E8="unassigned",0,(COUNTIF(I8:V8,1)*$C$6)*F8) -> 80
B9: Total Capacity in Hours: | C9: =SUM(W8:AB25) -> 340 | E9: IRM | F9: 1 | G9: 80 | I9: =IF(I$6<$E$3,0,IF(ISBLANK($E9),0,IF(I$6<$E$2,0,1))) -> 1 | J9: =IF(J$6<$E$3,0,IF(ISBLANK($E9),0,IF(J$6<$E$2,0,1))) -> 1 | K9: =IF(K$6<$E$3,0,IF(ISBLANK($E9),0,IF(K$6<$E$2,0,1))) -> 1 | L9: =IF(L$6<$E$3,0,IF(ISBLANK($E9),0,IF(L$6<$E$2,0,1))) -> 1 | M9: =IF(M$6<$E$3,0,IF(ISBLANK($E9),0,IF(M$6<$E$2,0,1))) -> 1 | N9: 8 | O9: 8 | P9: =IF(P$6<$E$3,0,IF(ISBLANK($E9),0,IF(P$6<$E$2,0,1))) -> 1 | Q9: =IF(Q$6<$E$3,0,IF(ISBLANK($E9),0,IF(Q$6<$E$2,0,1))) -> 1 | R9: =IF(R$6<$E$3,0,IF(ISBLANK($E9),0,IF(R$6<$E$2,0,1))) -> 1 | S9: =IF(S$6<$E$3,0,IF(ISBLANK($E9),0,IF(S$6<$E$2,0,1))) -> 1 | T9: =IF(T$6<$E$3,0,IF(ISBLANK($E9),0,IF(T$6<$E$2,0,1))) -> 1 | W9: =IF(E9="unassigned",0,(COUNTIF(I9:V9,1)*$C$6)*F9) -> 80
B10: Variance in Hours: | C10: =C8-C9 -> 0 | E10: INT3 | F10: 0.75 | G10: 60 | I10: =IF(I$6<$E$3,0,IF(ISBLANK($E10),0,IF(I$6<$E$2,0,1))) -> 1 | J10: =IF(J$6<$E$3,0,IF(ISBLANK($E10),0,IF(J$6<$E$2,0,1))) -> 1 | K10: =IF(K$6<$E$3,0,IF(ISBLANK($E10),0,IF(K$6<$E$2,0,1))) -> 1 | L10: =IF(L$6<$E$3,0,IF(ISBLANK($E10),0,IF(L$6<$E$2,0,1))) -> 1 | M10: =IF(M$6<$E$3,0,IF(ISBLANK($E10),0,IF(M$6<$E$2,0,1))) -> 1 | N10: 6 | O10: 6 | P10: =IF(P$6<$E$3,0,IF(ISBLANK($E10),0,IF(P$6<$E$2,0,1))) -> 1 | Q10: =IF(Q$6<$E$3,0,IF(ISBLANK($E10),0,IF(Q$6<$E$2,0,1))) -> 1 | R10: =IF(R$6<$E$3,0,IF(ISBLANK($E10),0,IF(R$6<$E$2,0,1))) -> 1 | S10: =IF(S$6<$E$3,0,IF(ISBLANK($E10),0,IF(S$6<$E$2,0,1))) -> 1 | T10: =IF(T$6<$E$3,0,IF(ISBLANK($E10),0,IF(T$6<$E$2,0,1))) -> 1 | W10: =IF(E10="unassigned",0,(COUNTIF(I10:V10,1)*$C$6)*F10) -> 60
E11: INT4 | F11: 0.75 | G11: 60 | I11: =IF(I$6<$E$3,0,IF(ISBLANK($E11),0,IF(I$6<$E$2,0,1))) -> 1 | J11: =IF(J$6<$E$3,0,IF(ISBLANK($E11),0,IF(J$6<$E$2,0,1))) -> 1 | K11: =IF(K$6<$E$3,0,IF(ISBLANK($E11),0,IF(K$6<$E$2,0,1))) -> 1 | L11: =IF(L$6<$E$3,0,IF(ISBLANK($E11),0,IF(L$6<$E$2,0,1))) -> 1 | M11: =IF(M$6<$E$3,0,IF(ISBLANK($E11),0,IF(M$6<$E$2,0,1))) -> 1 | N11: 6 | O11: 6 | P11: =IF(P$6<$E$3,0,IF(ISBLANK($E11),0,IF(P$6<$E$2,0,1))) -> 1 | Q11: =IF(Q$6<$E$3,0,IF(ISBLANK($E11),0,IF(Q$6<$E$2,0,1))) -> 1 | R11: =IF(R$6<$E$3,0,IF(ISBLANK($E11),0,IF(R$6<$E$2,0,1))) -> 1 | S11: =IF(S$6<$E$3,0,IF(ISBLANK($E11),0,IF(S$6<$E$2,0,1))) -> 1 | T11: =IF(T$6<$E$3,0,IF(ISBLANK($E11),0,IF(T$6<$E$2,0,1))) -> 1 | W11: =IF(E11="unassigned",0,(COUNTIF(I11:V11,1)*$C$6)*F11) -> 60
E12: SM | F12: 0.5 | G12: 40 | I12: =IF(I$6<$E$3,0,IF(ISBLANK($E12),0,IF(I$6<$E$2,0,1))) -> 1 | J12: =IF(J$6<$E$3,0,IF(ISBLANK($E12),0,IF(J$6<$E$2,0,1))) -> 1 | K12: =IF(K$6<$E$3,0,IF(ISBLANK($E12),0,IF(K$6<$E$2,0,1))) -> 1 | L12: =IF(L$6<$E$3,0,IF(ISBLANK($E12),0,IF(L$6<$E$2,0,1))) -> 1 | M12: =IF(M$6<$E$3,0,IF(ISBLANK($E12),0,IF(M$6<$E$2,0,1))) -> 1 | N12: 4 | O12: 4 | P12: =IF(P$6<$E$3,0,IF(ISBLANK($E12),0,IF(P$6<$E$2,0,1))) -> 1 | Q12: =IF(Q$6<$E$3,0,IF(ISBLANK($E12),0,IF(Q$6<$E$2,0,1))) -> 1 | R12: =IF(R$6<$E$3,0,IF(ISBLANK($E12),0,IF(R$6<$E$2,0,1))) -> 1 | S12: =IF(S$6<$E$3,0,IF(ISBLANK($E12),0,IF(S$6<$E$2,0,1))) -> 1 | T12: =IF(T$6<$E$3,0,IF(ISBLANK($E12),0,IF(T$6<$E$2,0,1))) -> 1 | W12: =IF(E12="unassigned",0,(COUNTIF(I12:V12,1)*$C$6)*F12) -> 40
E13: PO | F13: 0.25 | G13: 20 | I13: =IF(I$6<$E$3,0,IF(ISBLANK($E13),0,IF(I$6<$E$2,0,1))) -> 1 | J13: =IF(J$6<$E$3,0,IF(ISBLANK($E13),0,IF(J$6<$E$2,0,1))) -> 1 | K13: =IF(K$6<$E$3,0,IF(ISBLANK($E13),0,IF(K$6<$E$2,0,1))) -> 1 | L13: =IF(L$6<$E$3,0,IF(ISBLANK($E13),0,IF(L$6<$E$2,0,1))) -> 1 | M13: =IF(M$6<$E$3,0,IF(ISBLANK($E13),0,IF(M$6<$E$2,0,1))) -> 1 | N13: 2 | O13: 2 | P13: =IF(P$6<$E$3,0,IF(ISBLANK($E13),0,IF(P$6<$E$2,0,1))) -> 1 | Q13: =IF(Q$6<$E$3,0,IF(ISBLANK($E13),0,IF(Q$6<$E$2,0,1))) -> 1 | R13: =IF(R$6<$E$3,0,IF(ISBLANK($E13),0,IF(R$6<$E$2,0,1))) -> 1 | S13: =IF(S$6<$E$3,0,IF(ISBLANK($E13),0,IF(S$6<$E$2,0,1))) -> 1 | T13: =IF(T$6<$E$3,0,IF(ISBLANK($E13),0,IF(T$6<$E$2,0,1))) -> 1 | W13: =IF(E13="unassigned",0,(COUNTIF(I13:V13,1)*$C$6)*F13) -> 20
G14: =SUMIF(Sprint!$F$4:$F$1859,E14,Sprint!$AX$4:$AX$1859) -> 0 | I14: =IF(I$6<$E$3,0,IF(ISBLANK($E14),0,IF(I$6<$E$2,0,1))) -> 0 | J14: =IF(J$6<$E$3,0,IF(ISBLANK($E14),0,IF(J$6<$E$2,0,1))) -> 0 | K14: =IF(K$6<$E$3,0,IF(ISBLANK($E14),0,IF(K$6<$E$2,0,1))) -> 0 | L14: =IF(L$6<$E$3,0,IF(ISBLANK($E14),0,IF(L$6<$E$2,0,1))) -> 0 | M14: =IF(M$6<$E$3,0,IF(ISBLANK($E14),0,IF(M$6<$E$2,0,1))) -> 0 | P14: =IF(P$6<$E$3,0,IF(ISBLANK($E14),0,IF(P$6<$E$2,0,1))) -> 0 | Q14: =IF(Q$6<$E$3,0,IF(ISBLANK($E14),0,IF(Q$6<$E$2,0,1))) -> 0 | R14: =IF(R$6<$E$3,0,IF(ISBLANK($E14),0,IF(R$6<$E$2,0,1))) -> 0 | S14: =IF(S$6<$E$3,0,IF(ISBLANK($E14),0,IF(S$6<$E$2,0,1))) -> 0 | T14: =IF(T$6<$E$3,0,IF(ISBLANK($E14),0,IF(T$6<$E$2,0,1))) -> 0 | W14: =IF(E14="unassigned",0,(COUNTIF(I14:V14,1)*$C$6)*F14) -> 0
G15: =SUMIF(Sprint!$F$4:$F$1859,E15,Sprint!$AX$4:$AX$1859) -> 0 | I15: =IF(I$6<$E$3,0,IF(ISBLANK($E15),0,IF(I$6<$E$2,0,1))) -> 0 | J15: =IF(J$6<$E$3,0,IF(ISBLANK($E15),0,IF(J$6<$E$2,0,1))) -> 0 | K15: =IF(K$6<$E$3,0,IF(ISBLANK($E15),0,IF(K$6<$E$2,0,1))) -> 0 | L15: =IF(L$6<$E$3,0,IF(ISBLANK($E15),0,IF(L$6<$E$2,0,1))) -> 0 | M15: =IF(M$6<$E$3,0,IF(ISBLANK($E15),0,IF(M$6<$E$2,0,1))) -> 0 | P15: =IF(P$6<$E$3,0,IF(ISBLANK($E15),0,IF(P$6<$E$2,0,1))) -> 0 | Q15: =IF(Q$6<$E$3,0,IF(ISBLANK($E15),0,IF(Q$6<$E$2,0,1))) -> 0 | R15: =IF(R$6<$E$3,0,IF(ISBLANK($E15),0,IF(R$6<$E$2,0,1))) -> 0 | S15: =IF(S$6<$E$3,0,IF(ISBLANK($E15),0,IF(S$6<$E$2,0,1))) -> 0 | T15: =IF(T$6<$E$3,0,IF(ISBLANK($E15),0,IF(T$6<$E$2,0,1))) -> 0 | W15: =IF(E15="unassigned",0,(COUNTIF(I15:V15,1)*$C$6)*F15) -> 0
G16: =SUMIF(Sprint!$F$4:$F$1859,E16,Sprint!$AX$4:$AX$1859) -> 0 | I16: =IF(I$6<$E$3,0,IF(ISBLANK($E16),0,IF(I$6<$E$2,0,1))) -> 0 | J16: =IF(J$6<$E$3,0,IF(ISBLANK($E16),0,IF(J$6<$E$2,0,1))) -> 0 | K16: =IF(K$6<$E$3,0,IF(ISBLANK($E16),0,IF(K$6<$E$2,0,1))) -> 0 | L16: =IF(L$6<$E$3,0,IF(ISBLANK($E16),0,IF(L$6<$E$2,0,1))) -> 0 | M16: =IF(M$6<$E$3,0,IF(ISBLANK($E16),0,IF(M$6<$E$2,0,1))) -> 0 | P16: =IF(P$6<$E$3,0,IF(ISBLANK($E16),0,IF(P$6<$E$2,0,1))) -> 0 | Q16: =IF(Q$6<$E$3,0,IF(ISBLANK($E16),0,IF(Q$6<$E$2,0,1))) -> 0 | R16: =IF(R$6<$E$3,0,IF(ISBLANK($E16),0,IF(R$6<$E$2,0,1))) -> 0 | S16: =IF(S$6<$E$3,0,IF(ISBLANK($E16),0,IF(S$6<$E$2,0,1))) -> 0 | T16: =IF(T$6<$E$3,0,IF(ISBLANK($E16),0,IF(T$6<$E$2,0,1))) -> 0 | W16: =IF(E16="unassigned",0,(COUNTIF(I16:V16,1)*$C$6)*F16) -> 0
G17: =SUMIF(Sprint!$F$4:$F$1859,E17,Sprint!$AX$4:$AX$1859) -> 0 | I17: =IF(I$6<$E$3,0,IF(ISBLANK($E17),0,IF(I$6<$E$2,0,1))) -> 0 | J17: =IF(J$6<$E$3,0,IF(ISBLANK($E17),0,IF(J$6<$E$2,0,1))) -> 0 | K17: =IF(K$6<$E$3,0,IF(ISBLANK($E17),0,IF(K$6<$E$2,0,1))) -> 0 | L17: =IF(L$6<$E$3,0,IF(ISBLANK($E17),0,IF(L$6<$E$2,0,1))) -> 0 | M17: =IF(M$6<$E$3,0,IF(ISBLANK($E17),0,IF(M$6<$E$2,0,1))) -> 0 | P17: =IF(P$6<$E$3,0,IF(ISBLANK($E17),0,IF(P$6<$E$2,0,1))) -> 0 | Q17: =IF(Q$6<$E$3,0,IF(ISBLANK($E17),0,IF(Q$6<$E$2,0,1))) -> 0 | R17: =IF(R$6<$E$3,0,IF(ISBLANK($E17),0,IF(R$6<$E$2,0,1))) -> 0 | S17: =IF(S$6<$E$3,0,IF(ISBLANK($E17),0,IF(S$6<$E$2,0,1))) -> 0 | T17: =IF(T$6<$E$3,0,IF(ISBLANK($E17),0,IF(T$6<$E$2,0,1))) -> 0 | W17: =IF(E17="unassigned",0,(COUNTIF(I17:V17,1)*$C$6)*F17) -> 0
G18: =SUMIF(Sprint!$F$4:$F$1859,E18,Sprint!$AX$4:$AX$1859) -> 0 | I18: =IF(I$6<$E$3,0,IF(ISBLANK($E18),0,IF(I$6<$E$2,0,1))) -> 0 | J18: =IF(J$6<$E$3,0,IF(ISBLANK($E18),0,IF(J$6<$E$2,0,1))) -> 0 | K18: =IF(K$6<$E$3,0,IF(ISBLANK($E18),0,IF(K$6<$E$2,0,1))) -> 0 | L18: =IF(L$6<$E$3,0,IF(ISBLANK($E18),0,IF(L$6<$E$2,0,1))) -> 0 | M18: =IF(M$6<$E$3,0,IF(ISBLANK($E18),0,IF(M$6<$E$2,0,1))) -> 0 | P18: =IF(P$6<$E$3,0,IF(ISBLANK($E18),0,IF(P$6<$E$2,0,1))) -> 0 | Q18: =IF(Q$6<$E$3,0,IF(ISBLANK($E18),0,IF(Q$6<$E$2,0,1))) -> 0 | R18: =IF(R$6<$E$3,0,IF(ISBLANK($E18),0,IF(R$6<$E$2,0,1))) -> 0 | S18: =IF(S$6<$E$3,0,IF(ISBLANK($E18),0,IF(S$6<$E$2,0,1))) -> 0 | T18: =IF(T$6<$E$3,0,IF(ISBLANK($E18),0,IF(T$6<$E$2,0,1))) -> 0 | W18: =IF(E18="unassigned",0,(COUNTIF(I18:V18,1)*$C$6)*F18) -> 0
G19: =SUMIF(Sprint!$F$4:$F$1859,E19,Sprint!$AX$4:$AX$1859) -> 0 | I19: =IF(I$6<$E$3,0,IF(ISBLANK($E19),0,IF(I$6<$E$2,0,1))) -> 0 | J19: =IF(J$6<$E$3,0,IF(ISBLANK($E19),0,IF(J$6<$E$2,0,1))) -> 0 | K19: =IF(K$6<$E$3,0,IF(ISBLANK($E19),0,IF(K$6<$E$2,0,1))) -> 0 | L19: =IF(L$6<$E$3,0,IF(ISBLANK($E19),0,IF(L$6<$E$2,0,1))) -> 0 | M19: =IF(M$6<$E$3,0,IF(ISBLANK($E19),0,IF(M$6<$E$2,0,1))) -> 0 | P19: =IF(P$6<$E$3,0,IF(ISBLANK($E19),0,IF(P$6<$E$2,0,1))) -> 0 | Q19: =IF(Q$6<$E$3,0,IF(ISBLANK($E19),0,IF(Q$6<$E$2,0,1))) -> 0 | R19: =IF(R$6<$E$3,0,IF(ISBLANK($E19),0,IF(R$6<$E$2,0,1))) -> 0 | S19: =IF(S$6<$E$3,0,IF(ISBLANK($E19),0,IF(S$6<$E$2,0,1))) -> 0 | T19: =IF(T$6<$E$3,0,IF(ISBLANK($E19),0,IF(T$6<$E$2,0,1))) -> 0 | W19: =IF(E19="unassigned",0,(COUNTIF(I19:V19,1)*$C$6)*F19) -> 0
G20: =SUMIF(Sprint!$F$4:$F$1859,E20,Sprint!$AX$4:$AX$1859) -> 0 | I20: =IF(I$6<$E$3,0,IF(ISBLANK($E20),0,IF(I$6<$E$2,0,1))) -> 0 | J20: =IF(J$6<$E$3,0,IF(ISBLANK($E20),0,IF(J$6<$E$2,0,1))) -> 0 | K20: =IF(K$6<$E$3,0,IF(ISBLANK($E20),0,IF(K$6<$E$2,0,1))) -> 0 | L20: =IF(L$6<$E$3,0,IF(ISBLANK($E20),0,IF(L$6<$E$2,0,1))) -> 0 | M20: =IF(M$6<$E$3,0,IF(ISBLANK($E20),0,IF(M$6<$E$2,0,1))) -> 0 | P20: =IF(P$6<$E$3,0,IF(ISBLANK($E20),0,IF(P$6<$E$2,0,1))) -> 0 | Q20: =IF(Q$6<$E$3,0,IF(ISBLANK($E20),0,IF(Q$6<$E$2,0,1))) -> 0 | R20: =IF(R$6<$E$3,0,IF(ISBLANK($E20),0,IF(R$6<$E$2,0,1))) -> 0 | S20: =IF(S$6<$E$3,0,IF(ISBLANK($E20),0,IF(S$6<$E$2,0,1))) -> 0 | T20: =IF(T$6<$E$3,0,IF(ISBLANK($E20),0,IF(T$6<$E$2,0,1))) -> 0 | W20: =IF(E20="unassigned",0,(COUNTIF(I20:V20,1)*$C$6)*F20) -> 0
G21: =SUMIF(Sprint!$F$4:$F$1859,E21,Sprint!$AX$4:$AX$1859) -> 0 | I21: =IF(I$6<$E$3,0,IF(ISBLANK($E21),0,IF(I$6<$E$2,0,1))) -> 0 | J21: =IF(J$6<$E$3,0,IF(ISBLANK($E21),0,IF(J$6<$E$2,0,1))) -> 0 | K21: =IF(K$6<$E$3,0,IF(ISBLANK($E21),0,IF(K$6<$E$2,0,1))) -> 0 | L21: =IF(L$6<$E$3,0,IF(ISBLANK($E21),0,IF(L$6<$E$2,0,1))) -> 0 | M21: =IF(M$6<$E$3,0,IF(ISBLANK($E21),0,IF(M$6<$E$2,0,1))) -> 0 | P21: =IF(P$6<$E$3,0,IF(ISBLANK($E21),0,IF(P$6<$E$2,0,1))) -> 0 | Q21: =IF(Q$6<$E$3,0,IF(ISBLANK($E21),0,IF(Q$6<$E$2,0,1))) -> 0 | R21: =IF(R$6<$E$3,0,IF(ISBLANK($E21),0,IF(R$6<$E$2,0,1))) -> 0 | S21: =IF(S$6<$E$3,0,IF(ISBLANK($E21),0,IF(S$6<$E$2,0,1))) -> 0 | T21: =IF(T$6<$E$3,0,IF(ISBLANK($E21),0,IF(T$6<$E$2,0,1))) -> 0 | W21: =IF(E21="unassigned",0,(COUNTIF(I21:V21,1)*$C$6)*F21) -> 0
G22: =SUMIF(Sprint!$F$4:$F$1859,E22,Sprint!$AX$4:$AX$1859) -> 0 | I22: =IF(I$6<$E$3,0,IF(ISBLANK($E22),0,IF(I$6<$E$2,0,1))) -> 0 | J22: =IF(J$6<$E$3,0,IF(ISBLANK($E22),0,IF(J$6<$E$2,0,1))) -> 0 | K22: =IF(K$6<$E$3,0,IF(ISBLANK($E22),0,IF(K$6<$E$2,0,1))) -> 0 | L22: =IF(L$6<$E$3,0,IF(ISBLANK($E22),0,IF(L$6<$E$2,0,1))) -> 0 | M22: =IF(M$6<$E$3,0,IF(ISBLANK($E22),0,IF(M$6<$E$2,0,1))) -> 0 | P22: =IF(P$6<$E$3,0,IF(ISBLANK($E22),0,IF(P$6<$E$2,0,1))) -> 0 | Q22: =IF(Q$6<$E$3,0,IF(ISBLANK($E22),0,IF(Q$6<$E$2,0,1))) -> 0 | R22: =IF(R$6<$E$3,0,IF(ISBLANK($E22),0,IF(R$6<$E$2,0,1))) -> 0 | S22: =IF(S$6<$E$3,0,IF(ISBLANK($E22),0,IF(S$6<$E$2,0,1))) -> 0 | T22: =IF(T$6<$E$3,0,IF(ISBLANK($E22),0,IF(T$6<$E$2,0,1))) -> 0 | W22: =IF(E22="unassigned",0,(COUNTIF(I22:V22,1)*$C$6)*F22) -> 0
G23: =SUMIF(Sprint!$F$4:$F$1859,E23,Sprint!$AX$4:$AX$1859) -> 0 | I23: =IF(I$6<$E$3,0,IF(ISBLANK($E23),0,IF(I$6<$E$2,0,1))) -> 0 | J23: =IF(J$6<$E$3,0,IF(ISBLANK($E23),0,IF(J$6<$E$2,0,1))) -> 0 | K23: =IF(K$6<$E$3,0,IF(ISBLANK($E23),0,IF(K$6<$E$2,0,1))) -> 0 | L23: =IF(L$6<$E$3,0,IF(ISBLANK($E23),0,IF(L$6<$E$2,0,1))) -> 0 | M23: =IF(M$6<$E$3,0,IF(ISBLANK($E23),0,IF(M$6<$E$2,0,1))) -> 0 | P23: =IF(P$6<$E$3,0,IF(ISBLANK($E23),0,IF(P$6<$E$2,0,1))) -> 0 | Q23: =IF(Q$6<$E$3,0,IF(ISBLANK($E23),0,IF(Q$6<$E$2,0,1))) -> 0 | R23: =IF(R$6<$E$3,0,IF(ISBLANK($E23),0,IF(R$6<$E$2,0,1))) -> 0 | S23: =IF(S$6<$E$3,0,IF(ISBLANK($E23),0,IF(S$6<$E$2,0,1))) -> 0 | T23: =IF(T$6<$E$3,0,IF(ISBLANK($E23),0,IF(T$6<$E$2,0,1))) -> 0 | W23: =IF(E23="unassigned",0,(COUNTIF(I23:V23,1)*$C$6)*F23) -> 0
G24: =SUMIF(Sprint!$F$4:$F$1859,E24,Sprint!$AX$4:$AX$1859) -> 0 | I24: =IF(I$6<$E$3,0,IF(ISBLANK($E24),0,IF(I$6<$E$2,0,1))) -> 0 | J24: =IF(J$6<$E$3,0,IF(ISBLANK($E24),0,IF(J$6<$E$2,0,1))) -> 0 | K24: =IF(K$6<$E$3,0,IF(ISBLANK($E24),0,IF(K$6<$E$2,0,1))) -> 0 | L24: =IF(L$6<$E$3,0,IF(ISBLANK($E24),0,IF(L$6<$E$2,0,1))) -> 0 | M24: =IF(M$6<$E$3,0,IF(ISBLANK($E24),0,IF(M$6<$E$2,0,1))) -> 0 | P24: =IF(P$6<$E$3,0,IF(ISBLANK($E24),0,IF(P$6<$E$2,0,1))) -> 0 | Q24: =IF(Q$6<$E$3,0,IF(ISBLANK($E24),0,IF(Q$6<$E$2,0,1))) -> 0 | R24: =IF(R$6<$E$3,0,IF(ISBLANK($E24),0,IF(R$6<$E$2,0,1))) -> 0 | S24: =IF(S$6<$E$3,0,IF(ISBLANK($E24),0,IF(S$6<$E$2,0,1))) -> 0 | T24: =IF(T$6<$E$3,0,IF(ISBLANK($E24),0,IF(T$6<$E$2,0,1))) -> 0 | W24: =IF(E24="unassigned",0,(COUNTIF(I24:V24,1)*$C$6)*F24) -> 0
G25: =SUMIF(Sprint!$F$4:$F$1859,E25,Sprint!$AX$4:$AX$1859) -> 0 | I25: =IF(I$6<$E$3,0,IF(ISBLANK($E25),0,IF(I$6<$E$2,0,1))) -> 0 | J25: =IF(J$6<$E$3,0,IF(ISBLANK($E25),0,IF(J$6<$E$2,0,1))) -> 0 | K25: =IF(K$6<$E$3,0,IF(ISBLANK($E25),0,IF(K$6<$E$2,0,1))) -> 0 | L25: =IF(L$6<$E$3,0,IF(ISBLANK($E25),0,IF(L$6<$E$2,0,1))) -> 0 | M25: =IF(M$6<$E$3,0,IF(ISBLANK($E25),0,IF(M$6<$E$2,0,1))) -> 0 | P25: =IF(P$6<$E$3,0,IF(ISBLANK($E25),0,IF(P$6<$E$2,0,1))) -> 0 | Q25: =IF(Q$6<$E$3,0,IF(ISBLANK($E25),0,IF(Q$6<$E$2,0,1))) -> 0 | R25: =IF(R$6<$E$3,0,IF(ISBLANK($E25),0,IF(R$6<$E$2,0,1))) -> 0 | S25: =IF(S$6<$E$3,0,IF(ISBLANK($E25),0,IF(S$6<$E$2,0,1))) -> 0 | T25: =IF(T$6<$E$3,0,IF(ISBLANK($E25),0,IF(T$6<$E$2,0,1))) -> 0 | W25: =IF(E25="unassigned",0,(COUNTIF(I25:V25,1)*$C$6)*F25) -> 0
I29: v | J29: = | K29: Vacation & Public Holiday | Q29: h | R29: = | S29: OOF (Sick, Biz Travel etc.)

Sheet Analysis

Sheet Project Specific Reports
A1: Work Type Breakdown
A2: Feature | B2: =COUNTIF(Sprint!$A$4:$A$97, "Feature") -> 9 | C2: =B2/$B$6 -> 0.75
A3: Tax | B3: =COUNTIF(Sprint!$A$4:$A$97, "Tax") -> 2 | C3: =B3/$B$6 -> 0.16666667
A4: Precondition | B4: =COUNTIF(Sprint!$A$4:$A$97, "Precondition") -> 0 | C4: =B4/$B$6 -> 0
A5: Spike | B5: =COUNTIF(Sprint!$A$4:$A$97, "Spike") -> 1 | C5: =B5/$B$6 -> 0.083333333
A6: Total | B6: =SUM(B2:B5) -> 12 | C6: =SUM(C2:C5) -> 1
A8: Functional Breakdown
A9: Actividad 12 / Diccionario | B9: 1 | C9: 0.083333333
A10: Lectura de archivo | B10: 2 | C10: 0.16666667
A11: Búsqueda de tokens | B11: 3 | C11: 0.25
A12: Pruebas | B12: 2 | C12: =B12/$B$25 -> 0.16666667
A13: Documentación | B13: 2 | C13: =B13/$B$25 -> 0.16666667
A14: Revisión Scrum | B14: 2 | C14: =B14/$B$25 -> 0.16666667
C15: =B15/$B$25 -> 0
C16: =B16/$B$25 -> 0
C17: =B17/$B$25 -> 0
C18: =B18/$B$25 -> 0
C19: =B19/$B$25 -> 0
C20: =B20/$B$25 -> 0
C21: =B21/$B$25 -> 0
C22: =B22/$B$25 -> 0
C23: =B23/$B$25 -> 0
C24: =B24/$B$25 -> 0
A25: Total | B25: 12 | C25: 1
A27: Work Item Status | B27: Cantidad | C27: Porcentaje
A28: Complete | B28: 12 | C28: 1
A29: In Progress | B29: 0 | C29: =B29/$B$33 -> 0
A30: Pending | B30: 0 | C30: =B30/$B$33 -> 0
A31: Postponed | B31: 0 | C31: =B31/$B$33 -> 0
A32: Cancelled | B32: 0 | C32: =B32/$B$33 -> 0
A33: Total | B33: 12 | C33: 1

Sheet Sprint
F1: Start Date | G1: 46143 | J1: 46143 | M1: 46146 | P1: 46147 | S1: 46148 | V1: 46149 | Y1: 46150 | AB1: 46153 | AE1: 46154 | AH1: 46155 | AK1: 46156 | AN1: 46157 | AQ1: 46160 | AT1: =IF(AND(SkipWeekends, WEEKDAY(AQ1)=6),AQ1+3, AQ1+1) -> 46161 | AW1: =IF(AND(SkipWeekends, WEEKDAY(AT1)=6),AT1+3, AT1+1) -> 46162 | AZ1: =IF(AND(SkipWeekends, WEEKDAY(AW1)=6),AW1+3,AW1+ 1) -> 46163 | BC1: =IF(AND(SkipWeekends, WEEKDAY(AZ1)=6),AZ1+3, AZ1+1) -> 46164 | BF1: =IF(AND(SkipWeekends, WEEKDAY(BC1)=6),BC1+3, BC1+1) -> 46167 | BI1: =IF(AND(SkipWeekends, WEEKDAY(BF1)=6),BF1+3, BF1+1) -> 46168 | BL1: =IF(AND(SkipWeekends, WEEKDAY(BI1)=6),BI1+3, BI1+1) -> 46169 | BO1: =IF(AND(SkipWeekends, WEEKDAY(BL1)=6),BL1+3, BL1+1) -> 46170 | BR1: =IF(AND(SkipWeekends, WEEKDAY(BO1)=6),BO1+3, BO1+1) -> 46171 | BU1: =IF(AND(SkipWeekends, WEEKDAY(BR1)=6),BR1+3, BR1+1) -> 46174 | BX1: =IF(AND(SkipWeekends, WEEKDAY(BU1)=6),BU1+3, BU1+1) -> 46175 | CA1: =IF(AND(SkipWeekends, WEEKDAY(BX1)=6),BX1+3, BX1+1) -> 46176
J2: Day 1 | M2: Day 2 | P2: Day 3 | S2: Day 4 | V2: Day 5 | Y2: Day 6 | AB2: Day 7 | AE2: Day 8 | AH2: Day 9 | AK2: Day 10 | AN2: Day 11 | AQ2: Day 12 | AU2: Day 13 | AX2: Day 14 | BA2: Day 31 | BD2: Day 32 | BG2: Day 33 | BJ2: Day 34 | BM2: Day 35 | BP2: Day 36 | BS2: Day 37 | BV2: Day 38 | BY2: Day 39 | CB2: Day 40
A3: Worktype | B3: Deliverable Area | C3: Product Backlog Item or Group | D3: Work item ID | E3: Sprint Work item Description | F3: Driver | G3: Status | H3: Pri | I3: Initial | J3: Spent | K3: Left | L3: Estado | M3: Spent | N3: Left | O3: Estado | P3: Spent | Q3: Left | R3: Estado | S3: Spent | T3: Left | U3: Estado | V3: Spent | W3: Left | X3: Estado | Y3: Spent | Z3: Left | AA3: Estado | AB3: Spent | AC3: Left | AD3: Estado | AE3: Spent | AF3: Left | AG3: Estado | AH3: Spent | AI3: Left | AJ3: Estado | AK3: Spent | AL3: Left | AM3: Estado | AN3: Spent | AO3: Left | AP3: Estado | AQ3: Spent | AR3: Left | AS3: Estado | AT3: Spent | AU3: Left | AW3: Spent | AX3: Left | AZ3: Spent | BA3: Left | BC3: Spent | BD3: Left | BF3: Spent | BG3: Left | BI3: Spent | BJ3: Left | BL3: Spent | BM3: Left | BO3: Spent | BP3: Left | BR3: Spent | BS3: Left | BU3: Spent | BV3: Left | BX3: Spent | BY3: Left | CA3: Spent | CB3: Left | CE3: Total Effort
A4: Feature | B4: Actividad 12 / Diccionario | C4: Diccionario de tokens | D4: A12-001 | E4: Leer archivo diccionario generado en actividad anterior | F4: DIE | G4: Complete | H4: 1 | I4: 6 | J4: 0.5 | K4: =MAX(I4-J4, 0) -> 5.5 | L4: In Progress | M4: 0.2 | N4: =MAX(K4-M4,0) -> 5.3 | O4: In Progress | P4: 0.3 | Q4: =MAX(N4-P4,0) -> 5 | R4: In Progress | S4: 0.3 | T4: =MAX(Q4-S4,0) -> 4.7 | U4: In Progress | V4: 0.5 | W4: =MAX(T4-V4,0) -> 4.2 | X4: In Progress | Y4: 0.5 | Z4: =MAX(W4-Y4,0) -> 3.7 | AA4: In Progress | AB4: 0.5 | AC4: =MAX(Z4-AB4,0) -> 3.2 | AD4: In Progress | AE4: 0.6 | AF4: =MAX(AC4-AE4,0) -> 2.6 | AG4: In Progress | AH4: 0.8 | AI4: =MAX(AF4-AH4,0) -> 1.8 | AJ4: In Progress | AK4: 0.8 | AL4: =MAX(AI4-AK4,0) -> 1 | AM4: In Progress | AN4: 0.6 | AO4: =MAX(AL4-AN4,0) -> 0.4 | AP4: In Progress | AQ4: 0.4 | AR4: =MAX(AO4-AQ4,0) -> 0 | AS4: Complete | AU4: =MAX(AR4-AT4,0) -> 0 | AX4: =MAX(AU4-AW4,0) -> 0 | BD4: =MAX(BA4-BC4,0) -> 0 | BG4: =MAX(BD4-BF4,0) -> 0 | BJ4: =MAX(BG4-BI4,0) -> 0 | BM4: =MAX(BJ4-BL4,0) -> 0 | BP4: =MAX(BM4-BO4,0) -> 0 | BS4: =MAX(BP4-BR4,0) -> 0 | BV4: =MAX(BS4-BU4,0) -> 0 | BY4: =MAX(BV4-BX4,0) -> 0 | CB4: =MAX(BY4-CA4,0) -> 0
A5: Feature | B5: Lectura de archivo | C5: Diccionario de tokens | D5: A12-002 | E5: Validar formato index;key;numdocs;start | F5: IRM | G5: =(INDEX(Burndown,ROW(G5)-ROW(G$3),MIN(TODAY()-SprintStart,29)*3+3)) -> In Progress | H5: 1 | I5: 5 | J5: 0.4 | K5: =MAX(I5-J5, 0) -> 4.6 | L5: In Progress | M5: 0.2 | N5: =MAX(K5-M5,0) -> 4.4 | O5: In Progress | P5: 0.2 | Q5: =MAX(N5-P5,0) -> 4.2 | R5: In Progress | S5: 0.3 | T5: =MAX(Q5-S5,0) -> 3.9 | U5: In Progress | V5: 0.4 | W5: =MAX(T5-V5,0) -> 3.5 | X5: In Progress | Y5: 0.4 | Z5: =MAX(W5-Y5,0) -> 3.1 | AA5: In Progress | AB5: 0.4 | AC5: =MAX(Z5-AB5,0) -> 2.7 | AD5: In Progress | AE5: 0.6 | AF5: =MAX(AC5-AE5,0) -> 2.1 | AG5: In Progress | AH5: 0.6 | AI5: =MAX(AF5-AH5,0) -> 1.5 | AJ5: In Progress | AK5: 0.7 | AL5: =MAX(AI5-AK5,0) -> 0.8 | AM5: In Progress | AN5: 0.5 | AO5: =MAX(AL5-AN5,0) -> 0.3 | AP5: In Progress | AQ5: 0.3 | AR5: =MAX(AO5-AQ5,0) -> 0 | AS5: Complete | AU5: =MAX(AR5-AT5,0) -> 0 | AX5: =MAX(AU5-AW5,0) -> 0 | BA5: =MAX(AX5-AZ5,0) -> 0 | BD5: =MAX(BA5-BC5,0) -> 0 | BG5: =MAX(BD5-BF5,0) -> 0 | BJ5: =MAX(BG5-BI5,0) -> 0 | BM5: =MAX(BJ5-BL5,0) -> 0 | BP5: =MAX(BM5-BO5,0) -> 0 | BS5: =MAX(BP5-BR5,0) -> 0 | BV5: =MAX(BS5-BU5,0) -> 0 | BY5: =MAX(BV5-BX5,0) -> 0 | CB5: =MAX(BY5-CA5,0) -> 0
A6: Feature | B6: Búsqueda de tokens | C6: Diccionario de tokens | D6: A12-003 | E6: Implementar búsqueda por palabra exacta | F6: DIE | G6: =(INDEX(Burndown,ROW(G6)-ROW(G$3),MIN(TODAY()-SprintStart,29)*3+3)) -> In Progress | H6: 1 | I6: 8 | J6: 0.6 | K6: =MAX(I6-J6, 0) -> 7.4 | L6: In Progress | M6: 0.4 | N6: =MAX(K6-M6,0) -> 7 | O6: In Progress | P6: 0.3 | Q6: =MAX(N6-P6,0) -> 6.7 | R6: In Progress | S6: 0.5 | T6: =MAX(Q6-S6,0) -> 6.2 | U6: In Progress | V6: 0.6 | W6: =MAX(T6-V6,0) -> 5.6 | X6: In Progress | Y6: 0.6 | Z6: =MAX(W6-Y6,0) -> 5 | AA6: In Progress | AB6: 0.7 | AC6: =MAX(Z6-AB6,0) -> 4.3 | AD6: In Progress | AE6: 0.9 | AF6: =MAX(AC6-AE6,0) -> 3.4 | AG6: In Progress | AH6: 1 | AI6: =MAX(AF6-AH6,0) -> 2.4 | AJ6: In Progress | AK6: 1.1 | AL6: =MAX(AI6-AK6,0) -> 1.3 | AM6: In Progress | AN6: 0.8 | AO6: =MAX(AL6-AN6,0) -> 0.5 | AP6: In Progress | AQ6: 0.5 | AR6: =MAX(AO6-AQ6,0) -> 6.6613381e-16 | AS6: Complete | AU6: =MAX(AR6-AT6,0) -> 6.6613381e-16 | AX6: =MAX(AU6-AW6,0) -> 6.6613381e-16 | BA6: =MAX(AX6-AZ6,0) -> 6.6613381e-16 | BD6: =MAX(BA6-BC6,0) -> 6.6613381e-16 | BG6: =MAX(BD6-BF6,0) -> 6.6613381e-16 | BJ6: =MAX(BG6-BI6,0) -> 6.6613381e-16 | BM6: =MAX(BJ6-BL6,0) -> 6.6613381e-16 | BP6: =MAX(BM6-BO6,0) -> 6.6613381e-16 | BS6: =MAX(BP6-BR6,0) -> 6.6613381e-16 | BV6: =MAX(BS6-BU6,0) -> 6.6613381e-16 | BY6: =MAX(BV6-BX6,0) -> 6.6613381e-16 | CB6: =MAX(BY6-CA6,0) -> 6.6613381e-16
A7: Feature | B7: Búsqueda de tokens | C7: Diccionario de tokens | D7: A12-004 | E7: Implementar cálculo/hash para localizar índice | F7: INT3 | G7: =(INDEX(Burndown,ROW(G7)-ROW(G$3),MIN(TODAY()-SprintStart,29)*3+3)) -> In Progress | H7: 1 | I7: 8 | J7: 0.6 | K7: =MAX(I7-J7, 0) -> 7.4 | L7: In Progress | M7: 0.4 | N7: =MAX(K7-M7,0) -> 7 | O7: In Progress | P7: 0.3 | Q7: =MAX(N7-P7,0) -> 6.7 | R7: In Progress | S7: 0.5 | T7: =MAX(Q7-S7,0) -> 6.2 | U7: In Progress | V7: 0.6 | W7: =MAX(T7-V7,0) -> 5.6 | X7: In Progress | Y7: 0.6 | Z7: =MAX(W7-Y7,0) -> 5 | AA7: In Progress | AB7: 0.7 | AC7: =MAX(Z7-AB7,0) -> 4.3 | AD7: In Progress | AE7: 0.9 | AF7: =MAX(AC7-AE7,0) -> 3.4 | AG7: In Progress | AH7: 1 | AI7: =MAX(AF7-AH7,0) -> 2.4 | AJ7: In Progress | AK7: 1.1 | AL7: =MAX(AI7-AK7,0) -> 1.3 | AM7: In Progress | AN7: 0.8 | AO7: =MAX(AL7-AN7,0) -> 0.5 | AP7: In Progress | AQ7: 0.5 | AR7: =MAX(AO7-AQ7,0) -> 6.6613381e-16 | AS7: Complete | AU7: =MAX(AR7-AT7,0) -> 6.6613381e-16 | AX7: =MAX(AU7-AW7,0) -> 6.6613381e-16 | BA7: =MAX(AX7-AZ7,0) -> 6.6613381e-16 | BD7: =MAX(BA7-BC7,0) -> 6.6613381e-16 | BG7: =MAX(BD7-BF7,0) -> 6.6613381e-16 | BJ7: =MAX(BG7-BI7,0) -> 6.6613381e-16 | BM7: =MAX(BJ7-BL7,0) -> 6.6613381e-16 | BP7: =MAX(BM7-BO7,0) -> 6.6613381e-16 | BS7: =MAX(BP7-BR7,0) -> 6.6613381e-16 | BV7: =MAX(BS7-BU7,0) -> 6.6613381e-16 | BY7: =MAX(BV7-BX7,0) -> 6.6613381e-16 | CB7: =MAX(BY7-CA7,0) -> 6.6613381e-16
A8: Feature | B8: Búsqueda de tokens | C8: Diccionario de tokens | D8: A12-005 | E8: Mostrar numdocs y posición start del token encontrado | F8: INT4 | G8: =(INDEX(Burndown,ROW(G8)-ROW(G$3),MIN(TODAY()-SprintStart,29)*3+3)) -> In Progress | H8: 1 | I8: 6 | J8: 0.5 | K8: =MAX(I8-J8, 0) -> 5.5 | L8: In Progress | M8: 0.2 | N8: =MAX(K8-M8,0) -> 5.3 | O8: In Progress | P8: 0.3 | Q8: =MAX(N8-P8,0) -> 5 | R8: In Progress | S8: 0.3 | T8: =MAX(Q8-S8,0) -> 4.7 | U8: In Progress | V8: 0.5 | W8: =MAX(T8-V8,0) -> 4.2 | X8: In Progress | Y8: 0.5 | Z8: =MAX(W8-Y8,0) -> 3.7 | AA8: In Progress | AB8: 0.5 | AC8: =MAX(Z8-AB8,0) -> 3.2 | AD8: In Progress | AE8: 0.6 | AF8: =MAX(AC8-AE8,0) -> 2.6 | AG8: In Progress | AH8: 0.8 | AI8: =MAX(AF8-AH8,0) -> 1.8 | AJ8: In Progress | AK8: 0.8 | AL8: =MAX(AI8-AK8,0) -> 1 | AM8: In Progress | AN8: 0.6 | AO8: =MAX(AL8-AN8,0) -> 0.4 | AP8: In Progress | AQ8: 0.4 | AR8: =MAX(AO8-AQ8,0) -> 0 | AS8: Complete | AU8: =MAX(AR8-AT8,0) -> 0 | AX8: =MAX(AU8-AW8,0) -> 0 | BA8: =MAX(AX8-AZ8,0) -> 0 | BD8: =MAX(BA8-BC8,0) -> 0 | BG8: =MAX(BD8-BF8,0) -> 0 | BJ8: =MAX(BG8-BI8,0) -> 0 | BM8: =MAX(BJ8-BL8,0) -> 0 | BP8: =MAX(BM8-BO8,0) -> 0 | BS8: =MAX(BP8-BR8,0) -> 0 | BV8: =MAX(BS8-BU8,0) -> 0 | BY8: =MAX(BV8-BX8,0) -> 0 | CB8: =MAX(BY8-CA8,0) -> 0
A9: Feature | B9: Pruebas | C9: Diccionario de tokens | D9: A12-006 | E9: Probar búsqueda con palabras existentes | F9: IRM | G9: =(INDEX(Burndown,ROW(G9)-ROW(G$3),MIN(TODAY()-SprintStart,29)*3+3)) -> In Progress | H9: 2 | I9: 5 | J9: 0.4 | K9: =MAX(I9-J9, 0) -> 4.6 | L9: In Progress | M9: 0.2 | N9: =MAX(K9-M9,0) -> 4.4 | O9: In Progress | P9: 0.2 | Q9: =MAX(N9-P9,0) -> 4.2 | R9: In Progress | S9: 0.3 | T9: =MAX(Q9-S9,0) -> 3.9 | U9: In Progress | V9: 0.4 | W9: =MAX(T9-V9,0) -> 3.5 | X9: In Progress | Y9: 0.4 | Z9: =MAX(W9-Y9,0) -> 3.1 | AA9: In Progress | AB9: 0.4 | AC9: =MAX(Z9-AB9,0) -> 2.7 | AD9: In Progress | AE9: 0.6 | AF9: =MAX(AC9-AE9,0) -> 2.1 | AG9: In Progress | AH9: 0.6 | AI9: =MAX(AF9-AH9,0) -> 1.5 | AJ9: In Progress | AK9: 0.7 | AL9: =MAX(AI9-AK9,0) -> 0.8 | AM9: In Progress | AN9: 0.5 | AO9: =MAX(AL9-AN9,0) -> 0.3 | AP9: In Progress | AQ9: 0.3 | AR9: =MAX(AO9-AQ9,0) -> 0 | AS9: Complete | AU9: =MAX(AR9-AT9,0) -> 0 | AX9: =MAX(AU9-AW9,0) -> 0 | BA9: =MAX(AX9-AZ9,0) -> 0 | BD9: =MAX(BA9-BC9,0) -> 0 | BG9: =MAX(BD9-BF9,0) -> 0 | BJ9: =MAX(BG9-BI9,0) -> 0 | BM9: =MAX(BJ9-BL9,0) -> 0 | BP9: =MAX(BM9-BO9,0) -> 0 | BS9: =MAX(BP9-BR9,0) -> 0 | BV9: =MAX(BS9-BU9,0) -> 0 | BY9: =MAX(BV9-BX9,0) -> 0 | CB9: =MAX(BY9-CA9,0) -> 0
A10: Feature | B10: Pruebas | C10: Diccionario de tokens | D10: A12-007 | E10: Probar búsqueda con palabras inexistentes | F10: INT3 | G10: =(INDEX(Burndown,ROW(G10)-ROW(G$3),MIN(TODAY()-SprintStart,29)*3+3)) -> In Progress | H10: 2 | I10: 4 | J10: 0.3 | K10: =MAX(I10-J10, 0) -> 3.7 | L10: In Progress | M10: 0.2 | N10: =MAX(K10-M10,0) -> 3.5 | O10: In Progress | P10: 0.1 | Q10: =MAX(N10-P10,0) -> 3.4 | R10: In Progress | S10: 0.3 | T10: =MAX(Q10-S10,0) -> 3.1 | U10: In Progress | V10: 0.3 | W10: =MAX(T10-V10,0) -> 2.8 | X10: In Progress | Y10: 0.3 | Z10: =MAX(W10-Y10,0) -> 2.5 | AA10: In Progress | AB10: 0.3 | AC10: =MAX(Z10-AB10,0) -> 2.2 | AD10: In Progress | AE10: 0.5 | AF10: =MAX(AC10-AE10,0) -> 1.7 | AG10: In Progress | AH10: 0.5 | AI10: =MAX(AF10-AH10,0) -> 1.2 | AJ10: In Progress | AK10: 0.6 | AL10: =MAX(AI10-AK10,0) -> 0.6 | AM10: In Progress | AN10: 0.4 | AO10: =MAX(AL10-AN10,0) -> 0.2 | AP10: In Progress | AQ10: 0.2 | AR10: =MAX(AO10-AQ10,0) -> 6.1062266e-16 | AS10: Complete | AU10: =MAX(AR10-AT10,0) -> 6.1062266e-16 | AX10: =MAX(AU10-AW10,0) -> 6.1062266e-16 | BA10: =MAX(AX10-AZ10,0) -> 6.1062266e-16 | BD10: =MAX(BA10-BC10,0) -> 6.1062266e-16 | BG10: =MAX(BD10-BF10,0) -> 6.1062266e-16 | BJ10: =MAX(BG10-BI10,0) -> 6.1062266e-16 | BM10: =MAX(BJ10-BL10,0) -> 6.1062266e-16 | BP10: =MAX(BM10-BO10,0) -> 6.1062266e-16 | BS10: =MAX(BP10-BR10,0) -> 6.1062266e-16 | BV10: =MAX(BS10-BU10,0) -> 6.1062266e-16 | BY10: =MAX(BV10-BX10,0) -> 6.1062266e-16 | CB10: =MAX(BY10-CA10,0) -> 6.1062266e-16
A11: Tax | B11: Documentación | C11: Entrega | D11: A12-008 | E11: Documentar uso del programa y capturas de ejecución | F11: IRM | G11: =(INDEX(Burndown,ROW(G11)-ROW(G$3),MIN(TODAY()-SprintStart,29)*3+3)) -> In Progress | H11: 2 | I11: 5 | J11: 0.4 | K11: 4.6 | L11: In Progress | M11: 0.2 | N11: 4.4 | O11: In Progress | P11: 0.2 | Q11: =MAX(N11-P11,0) -> 4.2 | R11: In Progress | S11: 0.3 | T11: =MAX(Q11-S11,0) -> 3.9 | U11: In Progress | V11: 0.4 | W11: =MAX(T11-V11,0) -> 3.5 | X11: In Progress | Y11: 0.4 | Z11: =MAX(W11-Y11,0) -> 3.1 | AA11: In Progress | AB11: 0.4 | AC11: =MAX(Z11-AB11,0) -> 2.7 | AD11: In Progress | AE11: 0.6 | AF11: =MAX(AC11-AE11,0) -> 2.1 | AG11: In Progress | AH11: 0.6 | AI11: =MAX(AF11-AH11,0) -> 1.5 | AJ11: In Progress | AK11: 0.7 | AL11: =MAX(AI11-AK11,0) -> 0.8 | AM11: In Progress | AN11: 0.5 | AO11: =MAX(AL11-AN11,0) -> 0.3 | AP11: In Progress | AQ11: 0.3 | AR11: =MAX(AO11-AQ11,0) -> 4.9960036e-16 | AS11: Complete | AU11: =MAX(AR11-AT11,0) -> 4.9960036e-16 | AX11: =MAX(AU11-AW11,0) -> 4.9960036e-16 | BA11: =MAX(AX11-AZ11,0) -> 4.9960036e-16 | BD11: =MAX(BA11-BC11,0) -> 4.9960036e-16 | BG11: =MAX(BD11-BF11,0) -> 4.9960036e-16 | BJ11: =MAX(BG11-BI11,0) -> 4.9960036e-16 | BM11: =MAX(BJ11-BL11,0) -> 4.9960036e-16 | BP11: =MAX(BM11-BO11,0) -> 4.9960036e-16 | BS11: =MAX(BP11-BR11,0) -> 4.9960036e-16 | BV11: =MAX(BS11-BU11,0) -> 4.9960036e-16 | BY11: =MAX(BV11-BX11,0) -> 4.9960036e-16 | CB11: =MAX(BY11-CA11,0) -> 4.9960036e-16
A12: Spike | B12: Lectura de archivo | C12: Diccionario de tokens | D12: A12-009 | E12: Revisar manejo de errores de archivo no encontrado | F12: DIE | G12: =(INDEX(Burndown,ROW(G12)-ROW(G$3),MIN(TODAY()-SprintStart,29)*3+3)) -> In Progress | H12: 2 | I12: 4 | J12: 0.3 | K12: =MAX(I12-J12, 0) -> 3.7 | L12: In Progress | M12: 0.2 | N12: =MAX(K12-M12,0) -> 3.5 | O12: In Progress | P12: 0.1 | Q12: =MAX(N12-P12,0) -> 3.4 | R12: In Progress | S12: 0.3 | T12: =MAX(Q12-S12,0) -> 3.1 | U12: In Progress | V12: 0.3 | W12: =MAX(T12-V12,0) -> 2.8 | X12: In Progress | Y12: 0.3 | Z12: =MAX(W12-Y12,0) -> 2.5 | AA12: In Progress | AB12: 0.3 | AC12: =MAX(Z12-AB12,0) -> 2.2 | AD12: In Progress | AE12: 0.5 | AF12: =MAX(AC12-AE12,0) -> 1.7 | AG12: In Progress | AH12: 0.5 | AI12: =MAX(AF12-AH12,0) -> 1.2 | AJ12: In Progress | AK12: 0.6 | AL12: =MAX(AI12-AK12,0) -> 0.6 | AM12: In Progress | AN12: 0.4 | AO12: =MAX(AL12-AN12,0) -> 0.2 | AP12: In Progress | AQ12: 0.2 | AR12: =MAX(AO12-AQ12,0) -> 6.1062266e-16 | AS12: Complete | AU12: =MAX(AR12-AT12,0) -> 6.1062266e-16 | AX12: =MAX(AU12-AW12,0) -> 6.1062266e-16 | BA12: =MAX(AX12-AZ12,0) -> 6.1062266e-16 | BD12: =MAX(BA12-BC12,0) -> 6.1062266e-16 | BG12: =MAX(BD12-BF12,0) -> 6.1062266e-16 | BJ12: =MAX(BG12-BI12,0) -> 6.1062266e-16 | BM12: =MAX(BJ12-BL12,0) -> 6.1062266e-16 | BP12: =MAX(BM12-BO12,0) -> 6.1062266e-16 | BS12: =MAX(BP12-BR12,0) -> 6.1062266e-16 | BV12: =MAX(BS12-BU12,0) -> 6.1062266e-16 | BY12: =MAX(BV12-BX12,0) -> 6.1062266e-16 | CB12: =MAX(BY12-CA12,0) -> 6.1062266e-16
A13: Feature | B13: Revisión Scrum | C13: Scrum | D13: A12-010 | E13: Actualizar plantilla con 11 sprints concluidos | F13: SM | G13: =(INDEX(Burndown,ROW(G13)-ROW(G$3),MIN(TODAY()-SprintStart,29)*3+3)) -> In Progress | H13: 1 | I13: 6 | J13: 0.5 | K13: =MAX(I13-J13, 0) -> 5.5 | L13: In Progress | M13: 0.2 | N13: 5.3 | O13: In Progress | P13: 0.3 | Q13: =MAX(N13-P13,0) -> 5 | R13: In Progress | S13: 0.3 | T13: =MAX(Q13-S13,0) -> 4.7 | U13: In Progress | V13: 0.5 | W13: =MAX(T13-V13,0) -> 4.2 | X13: In Progress | Y13: 0.5 | Z13: =MAX(W13-Y13,0) -> 3.7 | AA13: In Progress | AB13: 0.5 | AC13: =MAX(Z13-AB13,0) -> 3.2 | AD13: In Progress | AE13: 0.6 | AF13: =MAX(AC13-AE13,0) -> 2.6 | AG13: In Progress | AH13: 0.8 | AI13: =MAX(AF13-AH13,0) -> 1.8 | AJ13: In Progress | AK13: 0.8 | AL13: =MAX(AI13-AK13,0) -> 1 | AM13: In Progress | AN13: 0.6 | AO13: =MAX(AL13-AN13,0) -> 0.4 | AP13: In Progress | AQ13: 0.4 | AR13: =MAX(AO13-AQ13,0) -> 0 | AS13: Complete | AU13: =MAX(AR13-AT13,0) -> 0 | AX13: =MAX(AU13-AW13,0) -> 0 | BA13: =MAX(AX13-AZ13,0) -> 0 | BD13: =MAX(BA13-BC13,0) -> 0 | BG13: =MAX(BD13-BF13,0) -> 0 | BJ13: =MAX(BG13-BI13,0) -> 0 | BM13: =MAX(BJ13-BL13,0) -> 0 | BP13: =MAX(BM13-BO13,0) -> 0 | BS13: =MAX(BP13-BR13,0) -> 0 | BV13: =MAX(BS13-BU13,0) -> 0 | BY13: =MAX(BV13-BX13,0) -> 0 | CB13: =MAX(BY13-CA13,0) -> 0
A14: Feature | B14: Revisión Scrum | C14: Scrum | D14: A12-011 | E14: Agregar sprint actual de Actividad 12 | F14: SM | G14: =(INDEX(Burndown,ROW(G14)-ROW(G$3),MIN(TODAY()-SprintStart,29)*3+3)) -> In Progress | H14: 1 | I14: 6 | J14: 0.5 | K14: =MAX(I14-J14, 0) -> 5.5 | L14: In Progress | M14: 0.2 | N14: =MAX(K14-M14,0) -> 5.3 | O14: In Progress | P14: 0.3 | Q14: =MAX(N14-P14,0) -> 5 | R14: In Progress | S14: 0.3 | T14: =MAX(Q14-S14,0) -> 4.7 | U14: In Progress | V14: 0.5 | W14: =MAX(T14-V14,0) -> 4.2 | X14: In Progress | Y14: 0.5 | Z14: =MAX(W14-Y14,0) -> 3.7 | AA14: In Progress | AB14: 0.5 | AC14: =MAX(Z14-AB14,0) -> 3.2 | AD14: In Progress | AE14: 0.6 | AF14: =MAX(AC14-AE14,0) -> 2.6 | AG14: In Progress | AH14: 0.8 | AI14: =MAX(AF14-AH14,0) -> 1.8 | AJ14: In Progress | AK14: 0.8 | AL14: =MAX(AI14-AK14,0) -> 1 | AM14: In Progress | AN14: 0.6 | AO14: =MAX(AL14-AN14,0) -> 0.4 | AP14: In Progress | AQ14: 0.4 | AR14: =MAX(AO14-AQ14,0) -> 0 | AS14: Complete | AU14: =MAX(AR14-AT14,0) -> 0 | AX14: =MAX(AU14-AW14,0) -> 0 | BA14: =MAX(AX14-AZ14,0) -> 0 | BD14: =MAX(BA14-BC14,0) -> 0 | BG14: =MAX(BD14-BF14,0) -> 0 | BJ14: =MAX(BG14-BI14,0) -> 0 | BM14: =MAX(BJ14-BL14,0) -> 0 | BP14: =MAX(BM14-BO14,0) -> 0 | BS14: =MAX(BP14-BR14,0) -> 0 | BV14: =MAX(BS14-BU14,0) -> 0 | BY14: =MAX(BV14-BX14,0) -> 0 | CB14: =MAX(BY14-CA14,0) -> 0
A15: Tax | B15: Documentación | C15: Entrega | D15: A12-012 | E15: Identificar perfil del burn down chart | F15: PO | G15: =(INDEX(Burndown,ROW(G15)-ROW(G$3),MIN(TODAY()-SprintStart,29)*3+3)) -> In Progress | H15: 1 | I15: 4 | J15: 0.3 | K15: =MAX(I15-J15, 0) -> 3.7 | L15: In Progress | M15: 0.2 | N15: =MAX(K15-M15,0) -> 3.5 | O15: In Progress | P15: 0.1 | Q15: =MAX(N15-P15,0) -> 3.4 | R15: In Progress | S15: 0.3 | T15: =MAX(Q15-S15,0) -> 3.1 | U15: In Progress | V15: 0.3 | W15: =MAX(T15-V15,0) -> 2.8 | X15: In Progress | Y15: 0.3 | Z15: =MAX(W15-Y15,0) -> 2.5 | AA15: In Progress | AB15: 0.3 | AC15: =MAX(Z15-AB15,0) -> 2.2 | AD15: In Progress | AE15: 0.5 | AF15: =MAX(AC15-AE15,0) -> 1.7 | AG15: In Progress | AH15: 0.5 | AI15: =MAX(AF15-AH15,0) -> 1.2 | AJ15: In Progress | AK15: 0.6 | AL15: =MAX(AI15-AK15,0) -> 0.6 | AM15: In Progress | AN15: 0.4 | AO15: =MAX(AL15-AN15,0) -> 0.2 | AP15: In Progress | AQ15: 0.2 | AR15: =MAX(AO15-AQ15,0) -> 6.1062266e-16 | AS15: Complete | AU15: =MAX(AR15-AT15,0) -> 6.1062266e-16 | AX15: =MAX(AU15-AW15,0) -> 6.1062266e-16 | BA15: =MAX(AX15-AZ15,0) -> 6.1062266e-16 | BD15: =MAX(BA15-BC15,0) -> 6.1062266e-16 | BG15: =MAX(BD15-BF15,0) -> 6.1062266e-16 | BJ15: =MAX(BG15-BI15,0) -> 6.1062266e-16 | BM15: =MAX(BJ15-BL15,0) -> 6.1062266e-16 | BP15: =MAX(BM15-BO15,0) -> 6.1062266e-16 | BS15: =MAX(BP15-BR15,0) -> 6.1062266e-16 | BV15: =MAX(BS15-BU15,0) -> 6.1062266e-16 | BY15: =MAX(BV15-BX15,0) -> 6.1062266e-16 | CB15: =MAX(BY15-CA15,0) -> 6.1062266e-16
G16: =(INDEX(Burndown,ROW(G16)-ROW(G$3),MIN(TODAY()-SprintStart,29)*3+3)) -> 0 | K16: =MAX(I16-J16, 0) -> 0 | N16: =MAX(K16-M16,0) -> 0 | Q16: =MAX(N16-P16,0) -> 0 | T16: =MAX(Q16-S16,0) -> 0 | W16: =MAX(T16-V16,0) -> 0 | Z16: =MAX(W16-Y16,0) -> 0 | AC16: =MAX(Z16-AB16,0) -> 0 | AF16: =MAX(AC16-AE16,0) -> 0 | AI16: =MAX(AF16-AH16,0) -> 0 | AL16: =MAX(AI16-AK16,0) -> 0 | AO16: =MAX(AL16-AN16,0) -> 0 | AR16: =MAX(AO16-AQ16,0) -> 0 | AU16: =MAX(AR16-AT16,0) -> 0 | AX16: =MAX(AU16-AW16,0) -> 0 | BA16: =MAX(AX16-AZ16,0) -> 0 | BD16: =MAX(BA16-BC16,0) -> 0 | BG16: =MAX(BD16-BF16,0) -> 0 | BJ16: =MAX(BG16-BI16,0) -> 0 | BM16: =MAX(BJ16-BL16,0) -> 0 | BP16: =MAX(BM16-BO16,0) -> 0 | BS16: =MAX(BP16-BR16,0) -> 0 | BV16: =MAX(BS16-BU16,0) -> 0 | BY16: =MAX(BV16-BX16,0) -> 0 | CB16: =MAX(BY16-CA16,0) -> 0
G17: =(INDEX(Burndown,ROW(G17)-ROW(G$3),MIN(TODAY()-SprintStart,29)*3+3)) -> 0 | K17: =MAX(I17-J17, 0) -> 0 | N17: =MAX(K17-M17,0) -> 0 | Q17: =MAX(N17-P17,0) -> 0 | T17: =MAX(Q17-S17,0) -> 0 | W17: =MAX(T17-V17,0) -> 0 | Z17: =MAX(W17-Y17,0) -> 0 | AC17: =MAX(Z17-AB17,0) -> 0 | AF17: =MAX(AC17-AE17,0) -> 0 | AI17: =MAX(AF17-AH17,0) -> 0 | AL17: =MAX(AI17-AK17,0) -> 0 | AO17: =MAX(AL17-AN17,0) -> 0 | AR17: =MAX(AO17-AQ17,0) -> 0 | AU17: =MAX(AR17-AT17,0) -> 0 | AX17: =MAX(AU17-AW17,0) -> 0 | BA17: =MAX(AX17-AZ17,0) -> 0 | BD17: =MAX(BA17-BC17,0) -> 0 | BG17: =MAX(BD17-BF17,0) -> 0 | BJ17: =MAX(BG17-BI17,0) -> 0 | BM17: =MAX(BJ17-BL17,0) -> 0 | BP17: =MAX(BM17-BO17,0) -> 0 | BS17: =MAX(BP17-BR17,0) -> 0 | BV17: =MAX(BS17-BU17,0) -> 0 | BY17: =MAX(BV17-BX17,0) -> 0 | CB17: =MAX(BY17-CA17,0) -> 0
G18: =(INDEX(Burndown,ROW(G18)-ROW(G$3),MIN(TODAY()-SprintStart,29)*3+3)) -> 0 | K18: =MAX(I18-J18, 0) -> 0 | N18: =MAX(K18-M18,0) -> 0 | Q18: =MAX(N18-P18,0) -> 0 | T18: =MAX(Q18-S18,0) -> 0 | W18: =MAX(T18-V18,0) -> 0 | Z18: =MAX(W18-Y18,0) -> 0 | AC18: =MAX(Z18-AB18,0) -> 0 | AF18: =MAX(AC18-AE18,0) -> 0 | AI18: =MAX(AF18-AH18,0) -> 0 | AL18: =MAX(AI18-AK18,0) -> 0 | AO18: =MAX(AL18-AN18,0) -> 0 | AR18: =MAX(AO18-AQ18,0) -> 0 | AU18: =MAX(AR18-AT18,0) -> 0 | AX18: =MAX(AU18-AW18,0) -> 0 | BA18: =MAX(AX18-AZ18,0) -> 0 | BD18: =MAX(BA18-BC18,0) -> 0 | BG18: =MAX(BD18-BF18,0) -> 0 | BJ18: =MAX(BG18-BI18,0) -> 0 | BM18: =MAX(BJ18-BL18,0) -> 0 | BP18: =MAX(BM18-BO18,0) -> 0 | BS18: =MAX(BP18-BR18,0) -> 0 | BV18: =MAX(BS18-BU18,0) -> 0 | BY18: =MAX(BV18-BX18,0) -> 0 | CB18: =MAX(BY18-CA18,0) -> 0
G19: =(INDEX(Burndown,ROW(G19)-ROW(G$3),MIN(TODAY()-SprintStart,29)*3+3)) -> 0 | K19: =MAX(I19-J19, 0) -> 0 | N19: =MAX(K19-M19,0) -> 0 | Q19: =MAX(N19-P19,0) -> 0 | T19: =MAX(Q19-S19,0) -> 0 | W19: =MAX(T19-V19,0) -> 0 | Z19: =MAX(W19-Y19,0) -> 0 | AC19: =MAX(Z19-AB19,0) -> 0 | AF19: =MAX(AC19-AE19,0) -> 0 | AI19: =MAX(AF19-AH19,0) -> 0 | AL19: =MAX(AI19-AK19,0) -> 0 | AO19: =MAX(AL19-AN19,0) -> 0 | AR19: =MAX(AO19-AQ19,0) -> 0 | AU19: =MAX(AR19-AT19,0) -> 0 | AX19: =MAX(AU19-AW19,0) -> 0 | BA19: =MAX(AX19-AZ19,0) -> 0 | BD19: =MAX(BA19-BC19,0) -> 0 | BG19: =MAX(BD19-BF19,0) -> 0 | BJ19: =MAX(BG19-BI19,0) -> 0 | BM19: =MAX(BJ19-BL19,0) -> 0 | BP19: =MAX(BM19-BO19,0) -> 0 | BS19: =MAX(BP19-BR19,0) -> 0 | BV19: =MAX(BS19-BU19,0) -> 0 | BY19: =MAX(BV19-BX19,0) -> 0 | CB19: =MAX(BY19-CA19,0) -> 0
G20: =(INDEX(Burndown,ROW(G20)-ROW(G$3),MIN(TODAY()-SprintStart,29)*3+3)) -> 0 | K20: =MAX(I20-J20, 0) -> 0 | N20: =MAX(K20-M20,0) -> 0 | Q20: =MAX(N20-P20,0) -> 0 | T20: =MAX(Q20-S20,0) -> 0 | W20: =MAX(T20-V20,0) -> 0 | Z20: =MAX(W20-Y20,0) -> 0 | AC20: =MAX(Z20-AB20,0) -> 0 | AF20: =MAX(AC20-AE20,0) -> 0 | AI20: =MAX(AF20-AH20,0) -> 0 | AL20: =MAX(AI20-AK20,0) -> 0 | AO20: =MAX(AL20-AN20,0) -> 0 | AR20: =MAX(AO20-AQ20,0) -> 0 | AU20: =MAX(AR20-AT20,0) -> 0 | AX20: =MAX(AU20-AW20,0) -> 0 | BA20: =MAX(AX20-AZ20,0) -> 0 | BD20: =MAX(BA20-BC20,0) -> 0 | BG20: =MAX(BD20-BF20,0) -> 0 | BJ20: =MAX(BG20-BI20,0) -> 0 | BM20: =MAX(BJ20-BL20,0) -> 0 | BP20: =MAX(BM20-BO20,0) -> 0 | BS20: =MAX(BP20-BR20,0) -> 0 | BV20: =MAX(BS20-BU20,0) -> 0 | BY20: =MAX(BV20-BX20,0) -> 0 | CB20: =MAX(BY20-CA20,0) -> 0
G21: =(INDEX(Burndown,ROW(G21)-ROW(G$3),MIN(TODAY()-SprintStart,29)*3+3)) -> 0 | K21: =MAX(I21-J21, 0) -> 0 | N21: =MAX(K21-M21,0) -> 0 | Q21: =MAX(N21-P21,0) -> 0 | T21: =MAX(Q21-S21,0) -> 0 | W21: =MAX(T21-V21,0) -> 0 | Z21: =MAX(W21-Y21,0) -> 0 | AC21: =MAX(Z21-AB21,0) -> 0 | AF21: =MAX(AC21-AE21,0) -> 0 | AI21: =MAX(AF21-AH21,0) -> 0 | AL21: =MAX(AI21-AK21,0) -> 0 | AO21: =MAX(AL21-AN21,0) -> 0 | AR21: =MAX(AO21-AQ21,0) -> 0 | AU21: =MAX(AR21-AT21,0) -> 0 | AX21: =MAX(AU21-AW21,0) -> 0 | BA21: =MAX(AX21-AZ21,0) -> 0 | BD21: =MAX(BA21-BC21,0) -> 0 | BG21: =MAX(BD21-BF21,0) -> 0 | BJ21: =MAX(BG21-BI21,0) -> 0 | BM21: =MAX(BJ21-BL21,0) -> 0 | BP21: =MAX(BM21-BO21,0) -> 0 | BS21: =MAX(BP21-BR21,0) -> 0 | BV21: =MAX(BS21-BU21,0) -> 0 | BY21: =MAX(BV21-BX21,0) -> 0 | CB21: =MAX(BY21-CA21,0) -> 0
G22: =(INDEX(Burndown,ROW(G22)-ROW(G$3),MIN(TODAY()-SprintStart,29)*3+3)) -> 0 | K22: =MAX(I22-J22, 0) -> 0 | N22: =MAX(K22-M22,0) -> 0 | Q22: =MAX(N22-P22,0) -> 0 | T22: =MAX(Q22-S22,0) -> 0 | W22: =MAX(T22-V22,0) -> 0 | Z22: =MAX(W22-Y22,0) -> 0 | AC22: =MAX(Z22-AB22,0) -> 0 | AF22: =MAX(AC22-AE22,0) -> 0 | AI22: =MAX(AF22-AH22,0) -> 0 | AL22: =MAX(AI22-AK22,0) -> 0 | AO22: =MAX(AL22-AN22,0) -> 0 | AR22: =MAX(AO22-AQ22,0) -> 0 | AU22: =MAX(AR22-AT22,0) -> 0 | AX22: =MAX(AU22-AW22,0) -> 0 | BA22: =MAX(AX22-AZ22,0) -> 0 | BD22: =MAX(BA22-BC22,0) -> 0 | BG22: =MAX(BD22-BF22,0) -> 0 | BJ22: =MAX(BG22-BI22,0) -> 0 | BM22: =MAX(BJ22-BL22,0) -> 0 | BP22: =MAX(BM22-BO22,0) -> 0 | BS22: =MAX(BP22-BR22,0) -> 0 | BV22: =MAX(BS22-BU22,0) -> 0 | BY22: =MAX(BV22-BX22,0) -> 0 | CB22: =MAX(BY22-CA22,0) -> 0
G23: =(INDEX(Burndown,ROW(G23)-ROW(G$3),MIN(TODAY()-SprintStart,29)*3+3)) -> 0 | K23: =MAX(I23-J23, 0) -> 0 | N23: =MAX(K23-M23,0) -> 0 | Q23: =MAX(N23-P23,0) -> 0 | T23: =MAX(Q23-S23,0) -> 0 | W23: =MAX(T23-V23,0) -> 0 | Z23: =MAX(W23-Y23,0) -> 0 | AC23: =MAX(Z23-AB23,0) -> 0 | AF23: =MAX(AC23-AE23,0) -> 0 | AI23: =MAX(AF23-AH23,0) -> 0 | AL23: =MAX(AI23-AK23,0) -> 0 | AO23: =MAX(AL23-AN23,0) -> 0 | AR23: =MAX(AO23-AQ23,0) -> 0 | AU23: =MAX(AR23-AT23,0) -> 0 | AX23: =MAX(AU23-AW23,0) -> 0 | BA23: =MAX(AX23-AZ23,0) -> 0 | BD23: =MAX(BA23-BC23,0) -> 0 | BG23: =MAX(BD23-BF23,0) -> 0 | BJ23: =MAX(BG23-BI23,0) -> 0 | BM23: =MAX(BJ23-BL23,0) -> 0 | BP23: =MAX(BM23-BO23,0) -> 0 | BS23: =MAX(BP23-BR23,0) -> 0 | BV23: =MAX(BS23-BU23,0) -> 0 | BY23: =MAX(BV23-BX23,0) -> 0 | CB23: =MAX(BY23-CA23,0) -> 0
G24: =(INDEX(Burndown,ROW(G24)-ROW(G$3),MIN(TODAY()-SprintStart,29)*3+3)) -> 0 | K24: =MAX(I24-J24, 0) -> 0 | N24: =MAX(K24-M24,0) -> 0 | Q24: =MAX(N24-P24,0) -> 0 | T24: =MAX(Q24-S24,0) -> 0 | W24: =MAX(T24-V24,0) -> 0 | Z24: =MAX(W24-Y24,0) -> 0 | AC24: =MAX(Z24-AB24,0) -> 0 | AF24: =MAX(AC24-AE24,0) -> 0 | AI24: =MAX(AF24-AH24,0) -> 0 | AL24: =MAX(AI24-AK24,0) -> 0 | AO24: =MAX(AL24-AN24,0) -> 0 | AR24: =MAX(AO24-AQ24,0) -> 0 | AU24: =MAX(AR24-AT24,0) -> 0 | AX24: =MAX(AU24-AW24,0) -> 0 | BA24: =MAX(AX24-AZ24,0) -> 0 | BD24: =MAX(BA24-BC24,0) -> 0 | BG24: =MAX(BD24-BF24,0) -> 0 | BJ24: =MAX(BG24-BI24,0) -> 0 | BM24: =MAX(BJ24-BL24,0) -> 0 | BP24: =MAX(BM24-BO24,0) -> 0 | BS24: =MAX(BP24-BR24,0) -> 0 | BV24: =MAX(BS24-BU24,0) -> 0 | BY24: =MAX(BV24-BX24,0) -> 0 | CB24: =MAX(BY24-CA24,0) -> 0
G25: =(INDEX(Burndown,ROW(G25)-ROW(G$3),MIN(TODAY()-SprintStart,29)*3+3)) -> 0 | K25: =MAX(I25-J25, 0) -> 0 | N25: =MAX(K25-M25,0) -> 0 | Q25: =MAX(N25-P25,0) -> 0 | T25: =MAX(Q25-S25,0) -> 0 | W25: =MAX(T25-V25,0) -> 0 | Z25: =MAX(W25-Y25,0) -> 0 | AC25: =MAX(Z25-AB25,0) -> 0 | AF25: =MAX(AC25-AE25,0) -> 0 | AI25: =MAX(AF25-AH25,0) -> 0 | AL25: =MAX(AI25-AK25,0) -> 0 | AO25: =MAX(AL25-AN25,0) -> 0 | AR25: =MAX(AO25-AQ25,0) -> 0 | AU25: =MAX(AR25-AT25,0) -> 0 | AX25: =MAX(AU25-AW25,0) -> 0 | BA25: =MAX(AX25-AZ25,0) -> 0 | BD25: =MAX(BA25-BC25,0) -> 0 | BG25: =MAX(BD25-BF25,0) -> 0 | BJ25: =MAX(BG25-BI25,0) -> 0 | BM25: =MAX(BJ25-BL25,0) -> 0 | BP25: =MAX(BM25-BO25,0) -> 0 | BS25: =MAX(BP25-BR25,0) -> 0 | BV25: =MAX(BS25-BU25,0) -> 0 | BY25: =MAX(BV25-BX25,0) -> 0 | CB25: =MAX(BY25-CA25,0) -> 0
G26: =(INDEX(Burndown,ROW(G26)-ROW(G$3),MIN(TODAY()-SprintStart,29)*3+3)) -> 0 | K26: =MAX(I26-J26, 0) -> 0 | N26: =MAX(K26-M26,0) -> 0 | Q26: =MAX(N26-P26,0) -> 0 | T26: =MAX(Q26-S26,0) -> 0 | W26: =MAX(T26-V26,0) -> 0 | Z26: =MAX(W26-Y26,0) -> 0 | AC26: =MAX(Z26-AB26,0) -> 0 | AF26: =MAX(AC26-AE26,0) -> 0 | AI26: =MAX(AF26-AH26,0) -> 0 | AL26: =MAX(AI26-AK26,0) -> 0 | AO26: =MAX(AL26-AN26,0) -> 0 | AR26: =MAX(AO26-AQ26,0) -> 0 | AU26: =MAX(AR26-AT26,0) -> 0 | AX26: =MAX(AU26-AW26,0) -> 0 | BA26: =MAX(AX26-AZ26,0) -> 0 | BD26: =MAX(BA26-BC26,0) -> 0 | BG26: =MAX(BD26-BF26,0) -> 0 | BJ26: =MAX(BG26-BI26,0) -> 0 | BM26: =MAX(BJ26-BL26,0) -> 0 | BP26: =MAX(BM26-BO26,0) -> 0 | BS26: =MAX(BP26-BR26,0) -> 0 | BV26: =MAX(BS26-BU26,0) -> 0 | BY26: =MAX(BV26-BX26,0) -> 0 | CB26: =MAX(BY26-CA26,0) -> 0
G27: =(INDEX(Burndown,ROW(G27)-ROW(G$3),MIN(TODAY()-SprintStart,29)*3+3)) -> 0 | K27: =MAX(I27-J27, 0) -> 0 | N27: =MAX(K27-M27,0) -> 0 | Q27: =MAX(N27-P27,0) -> 0 | T27: =MAX(Q27-S27,0) -> 0 | W27: =MAX(T27-V27,0) -> 0 | Z27: =MAX(W27-Y27,0) -> 0 | AC27: =MAX(Z27-AB27,0) -> 0 | AF27: =MAX(AC27-AE27,0) -> 0 | AI27: =MAX(AF27-AH27,0) -> 0 | AL27: =MAX(AI27-AK27,0) -> 0 | AO27: =MAX(AL27-AN27,0) -> 0 | AR27: =MAX(AO27-AQ27,0) -> 0 | AU27: =MAX(AR27-AT27,0) -> 0 | AX27: =MAX(AU27-AW27,0) -> 0 | BA27: =MAX(AX27-AZ27,0) -> 0 | BD27: =MAX(BA27-BC27,0) -> 0 | BG27: =MAX(BD27-BF27,0) -> 0 | BJ27: =MAX(BG27-BI27,0) -> 0 | BM27: =MAX(BJ27-BL27,0) -> 0 | BP27: =MAX(BM27-BO27,0) -> 0 | BS27: =MAX(BP27-BR27,0) -> 0 | BV27: =MAX(BS27-BU27,0) -> 0 | BY27: =MAX(BV27-BX27,0) -> 0 | CB27: =MAX(BY27-CA27,0) -> 0
... G29: =(INDEX(Burndown,ROW(G29)-ROW(G$3),MIN(TODAY()-SprintStart,29)*3+3)) -> 0 | K29: =MAX(I29-J29, 0) -> 0 | N29: =MAX(K29-M29,0) -> 0 | Q29: =MAX(N29-P29,0) -> 0 | T29: =MAX(Q29-S29,0) -> 0 | W29: =MAX(T29-V29,0) -> 0 | Z29: =MAX(W29-Y29,0) -> 0 | AC29: =MAX(Z29-AB29,0) -> 0 | AF29: =MAX(AC29-AE29,0) -> 0 | AI29: =MAX(AF29-AH29,0) -> 0 | AL29: =MAX(AI29-AK29,0) -> 0 | AO29: =MAX(AL29-AN29,0) -> 0 | AR29: =MAX(AO29-AQ29,0) -> 0 | AU29: =MAX(AR29-AT29,0) -> 0 | AX29: =MAX(AU29-AW29,0) -> 0 | BA29: =MAX(AX29-AZ29,0) -> 0 | BD29: =MAX(BA29-BC29,0) -> 0 | BG29: =MAX(BD29-BF29,0) -> 0 | BJ29: =MAX(BG29-BI29,0) -> 0 | BM29: =MAX(BJ29-BL29,0) -> 0 | BP29: =MAX(BM29-BO29,0) -> 0 | BS29: =MAX(BP29-BR29,0) -> 0 | BV29: =MAX(BS29-BU29,0) -> 0 | BY29: =MAX(BV29-BX29,0) -> 0 | CB29: =MAX(BY29-CA29,0) -> 0
G30: =(INDEX(Burndown,ROW(G30)-ROW(G$3),MIN(TODAY()-SprintStart,29)*3+3)) -> 0 | K30: =MAX(I30-J30, 0) -> 0 | N30: =MAX(K30-M30,0) -> 0 | Q30: =MAX(N30-P30,0) -> 0 | T30: =MAX(Q30-S30,0) -> 0 | W30: =MAX(T30-V30,0) -> 0 | Z30: =MAX(W30-Y30,0) -> 0 | AC30: =MAX(Z30-AB30,0) -> 0 | AF30: =MAX(AC30-AE30,0) -> 0 | AI30: =MAX(AF30-AH30,0) -> 0 | AL30: =MAX(AI30-AK30,0) -> 0 | AO30: =MAX(AL30-AN30,0) -> 0 | AR30: =MAX(AO30-AQ30,0) -> 0 | AU30: =MAX(AR30-AT30,0) -> 0 | AX30: =MAX(AU30-AW30,0) -> 0 | BD30: =MAX(BA30-BC30,0) -> 0 | BG30: =MAX(BD30-BF30,0) -> 0 | BJ30: =MAX(BG30-BI30,0) -> 0 | BM30: =MAX(BJ30-BL30,0) -> 0 | BP30: =MAX(BM30-BO30,0) -> 0 | BS30: =MAX(BP30-BR30,0) -> 0 | BV30: =MAX(BS30-BU30,0) -> 0 | BY30: =MAX(BV30-BX30,0) -> 0 | CB30: =MAX(BY30-CA30,0) -> 0
G31: =(INDEX(Burndown,ROW(G31)-ROW(G$3),MIN(TODAY()-SprintStart,29)*3+3)) -> 0 | K31: =MAX(I31-J31, 0) -> 0 | N31: =MAX(K31-M31,0) -> 0 | Q31: =MAX(N31-P31,0) -> 0 | T31: =MAX(Q31-S31,0) -> 0 | W31: =MAX(T31-V31,0) -> 0 | Z31: =MAX(W31-Y31,0) -> 0 | AC31: =MAX(Z31-AB31,0) -> 0 | AF31: =MAX(AC31-AE31,0) -> 0 | AI31: =MAX(AF31-AH31,0) -> 0 | AL31: =MAX(AI31-AK31,0) -> 0 | AO31: =MAX(AL31-AN31,0) -> 0 | AR31: =MAX(AO31-AQ31,0) -> 0 | AU31: =MAX(AR31-AT31,0) -> 0 | AX31: =MAX(AU31-AW31,0) -> 0 | BD31: =MAX(BA31-BC31,0) -> 0 | BG31: =MAX(BD31-BF31,0) -> 0 | BJ31: =MAX(BG31-BI31,0) -> 0 | BM31: =MAX(BJ31-BL31,0) -> 0 | BP31: =MAX(BM31-BO31,0) -> 0 | BS31: =MAX(BP31-BR31,0) -> 0 | BV31: =MAX(BS31-BU31,0) -> 0 | BY31: =MAX(BV31-BX31,0) -> 0 | CB31: =MAX(BY31-CA31,0) -> 0
G32: =(INDEX(Burndown,ROW(G32)-ROW(G$3),MIN(TODAY()-SprintStart,29)*3+3)) -> 0 | K32: =MAX(I32-J32, 0) -> 0 | N32: =MAX(K32-M32,0) -> 0 | Q32: =MAX(N32-P32,0) -> 0 | T32: =MAX(Q32-S32,0) -> 0 | W32: =MAX(T32-V32,0) -> 0 | Z32: =MAX(W32-Y32,0) -> 0 | AC32: =MAX(Z32-AB32,0) -> 0 | AF32: =MAX(AC32-AE32,0) -> 0 | AI32: =MAX(AF32-AH32,0) -> 0 | AL32: =MAX(AI32-AK32,0) -> 0 | AO32: =MAX(AL32-AN32,0) -> 0 | AR32: =MAX(AO32-AQ32,0) -> 0 | AU32: =MAX(AR32-AT32,0) -> 0 | AX32: =MAX(AU32-AW32,0) -> 0 | BD32: =MAX(BA32-BC32,0) -> 0 | BG32: =MAX(BD32-BF32,0) -> 0 | BJ32: =MAX(BG32-BI32,0) -> 0 | BM32: =MAX(BJ32-BL32,0) -> 0 | BP32: =MAX(BM32-BO32,0) -> 0 | BS32: =MAX(BP32-BR32,0) -> 0 | BV32: =MAX(BS32-BU32,0) -> 0 | BY32: =MAX(BV32-BX32,0) -> 0 | CB32: =MAX(BY32-CA32,0) -> 0
G33: =(INDEX(Burndown,ROW(G33)-ROW(G$3),MIN(TODAY()-SprintStart,29)*3+3)) -> 0 | K33: =MAX(I33-J33, 0) -> 0 | N33: =MAX(K33-M33,0) -> 0 | Q33: =MAX(N33-P33,0) -> 0 | T33: =MAX(Q33-S33,0) -> 0 | W33: =MAX(T33-V33,0) -> 0 | Z33: =MAX(W33-Y33,0) -> 0 | AC33: =MAX(Z33-AB33,0) -> 0 | AF33: =MAX(AC33-AE33,0) -> 0 | AI33: =MAX(AF33-AH33,0) -> 0 | AL33: =MAX(AI33-AK33,0) -> 0 | AO33: =MAX(AL33-AN33,0) -> 0 | AR33: =MAX(AO33-AQ33,0) -> 0 | AU33: =MAX(AR33-AT33,0) -> 0 | AX33: =MAX(AU33-AW33,0) -> 0 | BD33: =MAX(BA33-BC33,0) -> 0 | BG33: =MAX(BD33-BF33,0) -> 0 | BJ33: =MAX(BG33-BI33,0) -> 0 | BM33: =MAX(BJ33-BL33,0) -> 0 | BP33: =MAX(BM33-BO33,0) -> 0 | BS33: =MAX(BP33-BR33,0) -> 0 | BV33: =MAX(BS33-BU33,0) -> 0 | BY33: =MAX(BV33-BX33,0) -> 0 | CB33: =MAX(BY33-CA33,0) -> 0
G34: =(INDEX(Burndown,ROW(G34)-ROW(G$3),MIN(TODAY()-SprintStart,29)*3+3)) -> 0 | K34: =MAX(I34-J34, 0) -> 0 | N34: =MAX(K34-M34,0) -> 0 | Q34: =MAX(N34-P34,0) -> 0 | T34: =MAX(Q34-S34,0) -> 0 | W34: =MAX(T34-V34,0) -> 0 | Z34: =MAX(W34-Y34,0) -> 0 | AC34: =MAX(Z34-AB34,0) -> 0 | AF34: =MAX(AC34-AE34,0) -> 0 | AI34: =MAX(AF34-AH34,0) -> 0 | AL34: =MAX(AI34-AK34,0) -> 0 | AO34: =MAX(AL34-AN34,0) -> 0 | AR34: =MAX(AO34-AQ34,0) -> 0 | AU34: =MAX(AR34-AT34,0) -> 0 | AX34: =MAX(AU34-AW34,0) -> 0 | BD34: =MAX(BA34-BC34,0) -> 0 | BG34: =MAX(BD34-BF34,0) -> 0 | BJ34: =MAX(BG34-BI34,0) -> 0 | BM34: =MAX(BJ34-BL34,0) -> 0 | BP34: =MAX(BM34-BO34,0) -> 0 | BS34: =MAX(BP34-BR34,0) -> 0 | BV34: =MAX(BS34-BU34,0) -> 0 | BY34: =MAX(BV34-BX34,0) -> 0 | CB34: =MAX(BY34-CA34,0) -> 0
G35: =(INDEX(Burndown,ROW(G35)-ROW(G$3),MIN(TODAY()-SprintStart,29)*3+3)) -> 0 | K35: =MAX(I35-J35, 0) -> 0 | N35: =MAX(K35-M35,0) -> 0 | Q35: =MAX(N35-P35,0) -> 0 | T35: =MAX(Q35-S35,0) -> 0 | W35: =MAX(T35-V35,0) -> 0 | Z35: =MAX(W35-Y35,0) -> 0 | AC35: =MAX(Z35-AB35,0) -> 0 | AF35: =MAX(AC35-AE35,0) -> 0 | AI35: =MAX(AF35-AH35,0) -> 0 | AL35: =MAX(AI35-AK35,0) -> 0 | AO35: =MAX(AL35-AN35,0) -> 0 | AR35: =MAX(AO35-AQ35,0) -> 0 | AU35: =MAX(AR35-AT35,0) -> 0 | AX35: =MAX(AU35-AW35,0) -> 0 | BD35: =MAX(BA35-BC35,0) -> 0 | BG35: =MAX(BD35-BF35,0) -> 0 | BJ35: =MAX(BG35-BI35,0) -> 0 | BM35: =MAX(BJ35-BL35,0) -> 0 | BP35: =MAX(BM35-BO35,0) -> 0 | BS35: =MAX(BP35-BR35,0) -> 0 | BV35: =MAX(BS35-BU35,0) -> 0 | BY35: =MAX(BV35-BX35,0) -> 0 | CB35: =MAX(BY35-CA35,0) -> 0
G36: =(INDEX(Burndown,ROW(G36)-ROW(G$3),MIN(TODAY()-SprintStart,29)*3+3)) -> 0 | K36: =MAX(I36-J36, 0) -> 0 | N36: =MAX(K36-M36,0) -> 0 | Q36: =MAX(N36-P36,0) -> 0 | T36: =MAX(Q36-S36,0) -> 0 | W36: =MAX(T36-V36,0) -> 0 | Z36: =MAX(W36-Y36,0) -> 0 | AC36: =MAX(Z36-AB36,0) -> 0 | AF36: =MAX(AC36-AE36,0) -> 0 | AI36: =MAX(AF36-AH36,0) -> 0 | AL36: =MAX(AI36-AK36,0) -> 0 | AO36: =MAX(AL36-AN36,0) -> 0 | AR36: =MAX(AO36-AQ36,0) -> 0 | AU36: =MAX(AR36-AT36,0) -> 0 | AX36: =MAX(AU36-AW36,0) -> 0 | BD36: =MAX(BA36-BC36,0) -> 0 | BG36: =MAX(BD36-BF36,0) -> 0 | BJ36: =MAX(BG36-BI36,0) -> 0 | BM36: =MAX(BJ36-BL36,0) -> 0 | BP36: =MAX(BM36-BO36,0) -> 0 | BS36: =MAX(BP36-BR36,0) -> 0 | BV36: =MAX(BS36-BU36,0) -> 0 | BY36: =MAX(BV36-BX36,0) -> 0 | CB36: =MAX(BY36-CA36,0) -> 0
G37: =(INDEX(Burndown,ROW(G37)-ROW(G$3),MIN(TODAY()-SprintStart,29)*3+3)) -> 0 | K37: =MAX(I37-J37, 0) -> 0 | N37: =MAX(K37-M37,0) -> 0 | Q37: =MAX(N37-P37,0) -> 0 | T37: =MAX(Q37-S37,0) -> 0 | W37: =MAX(T37-V37,0) -> 0 | Z37: =MAX(W37-Y37,0) -> 0 | AC37: =MAX(Z37-AB37,0) -> 0 | AF37: =MAX(AC37-AE37,0) -> 0 | AI37: =MAX(AF37-AH37,0) -> 0 | AL37: =MAX(AI37-AK37,0) -> 0 | AO37: =MAX(AL37-AN37,0) -> 0 | AR37: =MAX(AO37-AQ37,0) -> 0 | AU37: =MAX(AR37-AT37,0) -> 0 | AX37: =MAX(AU37-AW37,0) -> 0 | BD37: =MAX(BA37-BC37,0) -> 0 | BG37: =MAX(BD37-BF37,0) -> 0 | BJ37: =MAX(BG37-BI37,0) -> 0 | BM37: =MAX(BJ37-BL37,0) -> 0 | BP37: =MAX(BM37-BO37,0) -> 0 | BS37: =MAX(BP37-BR37,0) -> 0 | BV37: =MAX(BS37-BU37,0) -> 0 | BY37: =MAX(BV37-BX37,0) -> 0 | CB37: =MAX(BY37-CA37,0) -> 0
G38: =(INDEX(Burndown,ROW(G38)-ROW(G$3),MIN(TODAY()-SprintStart,29)*3+3)) -> 0 | K38: =MAX(I38-J38, 0) -> 0 | N38: =MAX(K38-M38,0) -> 0 | Q38: =MAX(N38-P38,0) -> 0 | T38: =MAX(Q38-S38,0) -> 0 | W38: =MAX(T38-V38,0) -> 0 | Z38: =MAX(W38-Y38,0) -> 0 | AC38: =MAX(Z38-AB38,0) -> 0 | AF38: =MAX(AC38-AE38,0) -> 0 | AI38: =MAX(AF38-AH38,0) -> 0 | AL38: =MAX(AI38-AK38,0) -> 0 | AO38: =MAX(AL38-AN38,0) -> 0 | AR38: =MAX(AO38-AQ38,0) -> 0 | AU38: =MAX(AR38-AT38,0) -> 0 | AX38: =MAX(AU38-AW38,0) -> 0 | BD38: =MAX(BA38-BC38,0) -> 0 | BG38: =MAX(BD38-BF38,0) -> 0 | BJ38: =MAX(BG38-BI38,0) -> 0 | BM38: =MAX(BJ38-BL38,0) -> 0 | BP38: =MAX(BM38-BO38,0) -> 0 | BS38: =MAX(BP38-BR38,0) -> 0 | BV38: =MAX(BS38-BU38,0) -> 0 | BY38: =MAX(BV38-BX38,0) -> 0 | CB38: =MAX(BY38-CA38,0) -> 0
G39: =(INDEX(Burndown,ROW(G39)-ROW(G$3),MIN(TODAY()-SprintStart,29)*3+3)) -> 0 | K39: =MAX(I39-J39, 0) -> 0 | N39: =MAX(K39-M39,0) -> 0 | Q39: =MAX(N39-P39,0) -> 0 | T39: =MAX(Q39-S39,0) -> 0 | W39: =MAX(T39-V39,0) -> 0 | Z39: =MAX(W39-Y39,0) -> 0 | AC39: =MAX(Z39-AB39,0) -> 0 | AF39: =MAX(AC39-AE39,0) -> 0 | AI39: =MAX(AF39-AH39,0) -> 0 | AL39: =MAX(AI39-AK39,0) -> 0 | AO39: =MAX(AL39-AN39,0) -> 0 | AR39: =MAX(AO39-AQ39,0) -> 0 | AU39: =MAX(AR39-AT39,0) -> 0 | AX39: =MAX(AU39-AW39,0) -> 0 | BD39: =MAX(BA39-BC39,0) -> 0 | BG39: =MAX(BD39-BF39,0) -> 0 | BJ39: =MAX(BG39-BI39,0) -> 0 | BM39: =MAX(BJ39-BL39,0) -> 0 | BP39: =MAX(BM39-BO39,0) -> 0 | BS39: =MAX(BP39-BR39,0) -> 0 | BV39: =MAX(BS39-BU39,0) -> 0 | BY39: =MAX(BV39-BX39,0) -> 0 | CB39: =MAX(BY39-CA39,0) -> 0
G40: =(INDEX(Burndown,ROW(G40)-ROW(G$3),MIN(TODAY()-SprintStart,29)*3+3)) -> 0 | K40: =MAX(I40-J40, 0) -> 0 | N40: =MAX(K40-M40,0) -> 0 | Q40: =MAX(N40-P40,0) -> 0 | T40: =MAX(Q40-S40,0) -> 0 | W40: =MAX(T40-V40,0) -> 0 | Z40: =MAX(W40-Y40,0) -> 0 | AC40: =MAX(Z40-AB40,0) -> 0 | AF40: =MAX(AC40-AE40,0) -> 0 | AI40: =MAX(AF40-AH40,0) -> 0 | AL40: =MAX(AI40-AK40,0) -> 0 | AO40: =MAX(AL40-AN40,0) -> 0 | AR40: =MAX(AO40-AQ40,0) -> 0 | AU40: =MAX(AR40-AT40,0) -> 0 | AX40: =MAX(AU40-AW40,0) -> 0 | BD40: =MAX(BA40-BC40,0) -> 0 | BG40: =MAX(BD40-BF40,0) -> 0 | BJ40: =MAX(BG40-BI40,0) -> 0 | BM40: =MAX(BJ40-BL40,0) -> 0 | BP40: =MAX(BM40-BO40,0) -> 0 | BS40: =MAX(BP40-BR40,0) -> 0 | BV40: =MAX(BS40-BU40,0) -> 0 | BY40: =MAX(BV40-BX40,0) -> 0 | CB40: =MAX(BY40-CA40,0) -> 0
G41: =(INDEX(Burndown,ROW(G41)-ROW(G$3),MIN(TODAY()-SprintStart,29)*3+3)) -> 0 | K41: =MAX(I41-J41, 0) -> 0 | N41: =MAX(K41-M41,0) -> 0 | Q41: =MAX(N41-P41,0) -> 0 | T41: =MAX(Q41-S41,0) -> 0 | W41: =MAX(T41-V41,0) -> 0 | Z41: =MAX(W41-Y41,0) -> 0 | AC41: =MAX(Z41-AB41,0) -> 0 | AF41: =MAX(AC41-AE41,0) -> 0 | AI41: =MAX(AF41-AH41,0) -> 0 | AL41: =MAX(AI41-AK41,0) -> 0 | AO41: =MAX(AL41-AN41,0) -> 0 | AR41: =MAX(AO41-AQ41,0) -> 0 | AU41: =MAX(AR41-AT41,0) -> 0 | AX41: =MAX(AU41-AW41,0) -> 0 | BD41: =MAX(BA41-BC41,0) -> 0 | BG41: =MAX(BD41-BF41,0) -> 0 | BJ41: =MAX(BG41-BI41,0) -> 0 | BM41: =MAX(BJ41-BL41,0) -> 0 | BP41: =MAX(BM41-BO41,0) -> 0 | BS41: =MAX(BP41-BR41,0) -> 0 | BV41: =MAX(BS41-BU41,0) -> 0 | BY41: =MAX(BV41-BX41,0) -> 0 | CB41: =MAX(BY41-CA41,0) -> 0
...

Sheet Sprint History
A1: Sprint | B1: Actividad / Entregable | C1: Estado | D1: Horas iniciales | E1: Horas terminadas | F1: Observaciones
A2: 1 | B2: Actividad 1 | C2: Concluido | D2: 45 | E2: 45 | F2: Sprint cerrado
A3: 2 | B3: Actividad 2 | C3: Concluido | D3: 50 | E3: 50 | F3: Sprint cerrado
A4: 3 | B4: Actividad 3 | C4: Concluido | D4: 55 | E4: 55 | F4: Sprint cerrado
A5: 4 | B5: Actividad 4 | C5: Concluido | D5: 40 | E5: 40 | F5: Sprint cerrado
A6: 5 | B6: Actividad 5 | C6: Concluido | D6: 45 | E6: 45 | F6: Sprint cerrado
A7: 6 | B7: Actividad 6 | C7: Concluido | D7: 50 | E7: 50 | F7: Sprint cerrado
A8: 7 | B8: Actividad 7 | C8: Concluido | D8: 55 | E8: 55 | F8: Sprint cerrado
A9: 8 | B9: Actividad 8 | C9: Concluido | D9: 40 | E9: 40 | F9: Sprint cerrado
A10: 9 | B10: Actividad 9 | C10: Concluido | D10: 45 | E10: 45 | F10: Sprint cerrado
A11: 10 | B11: Actividad 10 | C11: Concluido | D11: 50 | E11: 50 | F11: Sprint cerrado
A12: 11 | B12: Actividad 11 | C12: Concluido | D12: 55 | E12: 55 | F12: Sprint cerrado
A13: 12 | B13: Actividad 12 - Diccionario de tokens | C13: Sprint actual mostrado | D13: 67 | E13: 67 | F13: Perfil burn down: avance tardío / hockey stick
